<?xml version="1.0" ?>
<!-- =================================================================================== -->
<!-- |    This document was autogenerated by xacro from /home/fandes/workspace/kuavo-ros-control/src/humanoid-control/humanoid_interface_drake/models/biped_gen4.0/urdf/biped_v3_arm.xacro | -->
<!-- |    EDITING THIS FILE BY HAND IS NOT RECOMMENDED                                 | -->
<!-- =================================================================================== -->
<robot name="biped_v3_arm" xmlns:drake="https://drake.mit.edu">
  <link name="torso">
    <inertial>
      <origin rpy="0 0 0" xyz="0.00383143 0.0 0.18350901"/>
      <mass value="30.6186395"/>
      <inertia ixx="0.95851611" ixy="0.00026968" ixz="0.06381351" iyy="0.83635568" iyz="0.00069789" izz="0.29474019"/>
    </inertial>
    <visual>
      <origin rpy="0 0 0" xyz="0 0 0"/>
      <geometry>
        <mesh filename="../../meshes/torso.STL"/>
      </geometry>
      <material name="">
        <color rgba="0.43137 0.45098 0.43137 1"/>
      </material>
    </visual>
    <!-- <collision>
      <origin xyz="0 0 0" rpy="0 0 0" />
      <geometry>
        <mesh filename="../../meshes/torso.STL" />
      </geometry>
    </collision> -->
  </link>
  <!-- =========================================================== Arms ================================================================= -->
  
  <link name="zarm_l1_link">
    <inertial>
      <origin xyz="-0.00082795 -0.02218018 0.00035481" rpy="0 0 0" />
      <mass value="0.962" />
      <inertia ixx="0.00224654" ixy="2.728e-05" ixz="1.31e-06" iyy="0.0009868" iyz="1.728e-05" izz="0.00227089" />
    </inertial>
    <visual>
      <origin xyz="0 0 0" rpy="0 0 0" />
      <geometry>
        <mesh filename="../../meshes/l_arm_pitch.STL" />
      </geometry>
      <material name="">
        <color rgba="1 1 1 1" />
      </material>
    </visual>
  </link>
  <joint name="zarm_l1_joint" type="continuous">
    <origin xyz="-0.0174998525199963 0.2927 0.324500000000001" rpy="0 0 0" />
    <parent link="torso" />
    <child link="zarm_l1_link" />
    <axis xyz="0 1 0" />
    <limit lower="-2.0933" upper="1.5233" effort="100" velocity="100" />
  </joint>
  <transmission type="SimpleTransmission">
    <joint name="zarm_l1_joint"/>
    <actuator name="l_arm_pitch_motor"/>
  </transmission>
  <link name="zarm_l2_link">
    <inertial>
      <origin xyz="-0.00791105 -3.87e-06 -0.04655228" rpy="0 0 0" />
      <mass value="0.57" />
      <inertia ixx="0.00162944" ixy="3e-08" ixz="-5.271e-05" iyy="0.00211343" iyz="-9e-08" izz="0.00121954" />
    </inertial>
    <visual>
      <origin xyz="0 0 0" rpy="0 0 0" />
      <geometry>
        <mesh filename="../../meshes/l_arm_roll.STL" />
      </geometry>
      <material name="">
        <color rgba="1 1 1 1" />
      </material>
    </visual>
  </link>
  <joint name="zarm_l2_joint" type="continuous">
    <origin xyz="0 0 0" rpy="0 0 0" />
    <parent link="zarm_l1_link" />
    <child link="zarm_l2_link" />
    <axis xyz="1 0 0" />
    <limit lower="-1.57" upper="2.0933" effort="100" velocity="100" />
  </joint>
  <transmission type="SimpleTransmission">
    <joint name="zarm_l2_joint"/>
    <actuator name="l_arm_roll_motor"/>
  </transmission>
  <link name="zarm_l3_link">
    <inertial>
      <origin xyz="0.00628241 0.00106989 -0.20877733" rpy="0 0 0" />
      <mass value="1.65" />
      <inertia ixx="0.00814976" ixy="3.8e-05" ixz="-0.00084931" iyy="0.00827526" iyz="-0.00013592" izz="0.00206288" />
    </inertial>
    <visual>
      <origin xyz="0 0 0" rpy="0 0 0" />
      <geometry>
        <mesh filename="../../meshes/l_arm_yaw.STL" />
      </geometry>
      <material name="">
        <color rgba="1 1 1 1" />
      </material>
    </visual>
  </link>
  <joint name="zarm_l3_joint" type="continuous">
    <origin xyz="0 0 0" rpy="0 0 0" />
    <parent link="zarm_l2_link" />
    <child link="zarm_l3_link" />
    <axis xyz="0 0 1" />
    <limit lower="-1.57" upper="1.57" effort="100" velocity="100" />
  </joint>
  <transmission type="SimpleTransmission">
    <joint name="zarm_l3_joint"/>
    <actuator name="l_arm_yaw_motor"/>
  </transmission>
  <link name="zarm_l4_link">
    <inertial>
      <origin xyz="-0.01610688 0.00142664 -0.04856581" rpy="0 0 0" />
      <mass value="0.429" />
      <inertia ixx="0.00134692" ixy="2.97e-06" ixz="9.606e-05" iyy="0.00114093" iyz="4.24e-06" izz="0.00082821" />
    </inertial>
    <visual>
      <origin xyz="0 0 0" rpy="0 0 0" />
      <geometry>
        <mesh filename="../../meshes/l_foream.STL" />
      </geometry>
      <material name="">
        <color rgba="1 1 1 1" />
      </material>
    </visual>
  </link>
  <joint name="zarm_l4_joint" type="continuous">
    <origin xyz="0.0200000000000006 0 -0.2837" rpy="0 0 0" />
    <parent link="zarm_l3_link" />
    <child link="zarm_l4_link" />
    <axis xyz="0 1 0" />
    <limit lower="-2.44" upper="1.57" effort="100" velocity="100" />
  </joint>
  <transmission type="SimpleTransmission">
    <joint name="zarm_l4_joint"/>
    <actuator name="l_forearm_pitch_motor"/>
  </transmission>
  <link name="zarm_l5_link">
    <inertial>
      <origin xyz="-0.00207477 0.00017906 -0.0507928" rpy="0 0 0" />
      <mass value="0.61" />
      <inertia ixx="0.00106724" ixy="9e-07" ixz="4.124e-05" iyy="0.00145981" iyz="2.7e-07" izz="0.00083234" />
    </inertial>
    <visual>
      <origin xyz="0 0 0" rpy="0 0 0" />
      <geometry>
        <mesh filename="../../meshes/l_hand_yaw.STL" />
      </geometry>
      <material name="">
        <color rgba="1 1 1 1" />
      </material>
    </visual>
  </link>
  <joint name="zarm_l5_joint" type="continuous">
    <origin xyz="-0.0200000000000011 0 -0.127037274261586" rpy="0 0 0" />
    <parent link="zarm_l4_link" />
    <child link="zarm_l5_link" />
    <axis xyz="0 0 1" />
    <limit lower="-1.657" upper="1.657" effort="100" velocity="100" />
  </joint>
  <transmission type="SimpleTransmission">
    <joint name="zarm_l5_joint"/>
    <actuator name="l_hand_yaw_motor"/>
  </transmission>
  <link name="zarm_l6_link">
    <inertial>
      <origin xyz="-0.00111113 0.00325842 -0.01337608" rpy="0 0 0" />
      <mass value="0.331" />
      <inertia ixx="0.00022086" ixy="1.3e-06" ixz="-4.7e-06" iyy="0.00026819" iyz="-1.23e-06" izz="0.00028192" />
    </inertial>
    <visual>
      <origin xyz="0 0 0" rpy="0 0 0" />
      <geometry>
        <mesh filename="../../meshes/l_hand_roll.STL" />
      </geometry>
      <material name="">
        <color rgba="1 1 1 1" />
      </material>
    </visual>
  </link>
  <joint name="zarm_l6_joint" type="continuous">
    <origin xyz="0.000199999999999024 0 -0.106462725738415" rpy="0 0 0" />
    <parent link="zarm_l5_link" />
    <child link="zarm_l6_link" />
    <axis xyz="1 0 0" />
    <limit lower="-1.57" upper="1.57" effort="100" velocity="100" />
  </joint>
  <transmission type="SimpleTransmission">
    <joint name="zarm_l6_joint"/>
    <actuator name="l_hand_pitch_motor"/>
  </transmission>
  <link name="zarm_l7_link">
    <inertial>
      <origin xyz="0.00186349 0.00939991 -0.09050871" rpy="0 0 0" />
      <mass value="0.64" />
      <inertia ixx="0.0007064" ixy="-1.482e-05" ixz="-2.353e-05" iyy="0.00069691" iyz="4.308e-05" izz="0.00012495" />
    </inertial>
    <visual>
      <origin xyz="0 0 0" rpy="0 0 0" />
      <geometry>
        <mesh filename="../../meshes/l_hand_pitch.STL" />
      </geometry>
      <material name="">
        <color rgba="1 1 1 1" />
      </material>
    </visual>
  </link>
  <joint name="zarm_l7_joint" type="continuous">
    <origin xyz="0 0 -0.0209999999999996" rpy="0 0 0" />
    <parent link="zarm_l6_link" />
    <child link="zarm_l7_link" />
    <axis xyz="0 1 0" />
    <limit lower="-1.657" upper="1.657" effort="100" velocity="100" />
  </joint>
  <link name="zarm_l7_end_effector">
    <collision>
      <origin rpy="0 0 0" xyz="0 0 0" />
      <geometry>
        <sphere radius="0.005" />
      </geometry>
    </collision>
  </link>
  <joint name="zarm_l7_end_effector_joint" type="fixed">
    <origin xyz="0.0 -0.03 -0.17" rpy="0 0 0" />
    <parent link="zarm_l7_link" />
    <child link="zarm_l7_end_effector" />
  </joint>
  <transmission type="SimpleTransmission">
    <joint name="zarm_l7_end_effector_joint"/>
    <actuator name="l_hand_roll_motor"/>
  </transmission>
  <link name="zarm_r1_link">
    <inertial>
      <origin xyz="-0.00437587 0.02312496 0.00025053" rpy="0 0 0" />
      <mass value="0.962" />
      <inertia ixx="0.00121264" ixy="3.055e-05" ixz="5.2e-07" iyy="0.00054827" iyz="-5.04e-06" izz="0.00128011" />
    </inertial>
    <visual>
      <origin xyz="0 0 0" rpy="0 0 0" />
      <geometry>
        <mesh filename="../../meshes/r_arm_pitch.STL" />
      </geometry>
      <material name="">
        <color rgba="1 1 1 1" />
      </material>
    </visual>
  </link>
  <joint name="zarm_r1_joint" type="continuous">
    <origin xyz="-0.0174998525199963 -0.2927 0.324500000000001" rpy="0 0 0" />
    <parent link="torso" />
    <child link="zarm_r1_link" />
    <axis xyz="0 1 0" />
    <limit lower="-2.0933" upper="1.5233" effort="100" velocity="100" />
  </joint>
  <transmission type="SimpleTransmission">
    <joint name="zarm_r1_joint"/>
    <actuator name="r_arm_pitch_motor"/>
  </transmission>
  <link name="zarm_r2_link">
    <inertial>
      <origin xyz="-0.00790107 -3.72e-06 -0.04669902" rpy="0 0 0" />
      <mass value="0.57" />
      <inertia ixx="0.00059476" ixy="2e-08" ixz="-1.879e-05" iyy="0.00077187" iyz="-3e-08" izz="0.00044555" />
    </inertial>
    <visual>
      <origin xyz="0 0 0" rpy="0 0 0" />
      <geometry>
        <mesh filename="../../meshes/r_arm_roll.STL" />
      </geometry>
      <material name="">
        <color rgba="1 1 1 1" />
      </material>
    </visual>
  </link>
  <joint name="zarm_r2_joint" type="continuous">
    <origin xyz="0 0 0" rpy="0 0 0" />
    <parent link="zarm_r1_link" />
    <child link="zarm_r2_link" />
    <axis xyz="1 0 0" />
    <limit lower="-1.57" upper="2.0933" effort="100" velocity="100" />
  </joint>
  <transmission type="SimpleTransmission">
    <joint name="zarm_r2_joint"/>
    <actuator name="r_arm_roll_motor"/>
  </transmission>
  <link name="zarm_r3_link">
    <inertial>
      <origin xyz="0.00633246 -0.00090927 -0.20892968" rpy="0 0 0" />
      <mass value="1.65" />
      <inertia ixx="0.00252686" ixy="-1.115e-05" ixz="-0.00025634" iyy="0.00257097" iyz="3.771e-05" izz="0.00064839" />
    </inertial>
    <visual>
      <origin xyz="0 0 0" rpy="0 0 0" />
      <geometry>
        <mesh filename="../../meshes/r_arm_yaw.STL" />
      </geometry>
      <material name="">
        <color rgba="1 1 1 1" />
      </material>
    </visual>
  </link>
  <joint name="zarm_r3_joint" type="continuous">
    <origin xyz="0 0 0" rpy="0 0 0" />
    <parent link="zarm_r2_link" />
    <child link="zarm_r3_link" />
    <axis xyz="0 0 1" />
    <limit lower="-1.57" upper="1.57" effort="100" velocity="100" />
  </joint>
  <transmission type="SimpleTransmission">
    <joint name="zarm_r3_joint"/>
    <actuator name="r_arm_yaw_motor"/>
  </transmission>
  <link name="zarm_r4_link">
    <inertial>
      <origin xyz="-0.01692389 -0.00104775 -0.05206212" rpy="0 0 0" />
      <mass value="0.429" />
      <inertia ixx="0.00074673" ixy="-2.01e-06" ixz="5.925e-05" iyy="0.00064231" iyz="-6.21e-06" izz="0.00044314" />
    </inertial>
    <visual>
      <origin xyz="0 0 0" rpy="0 0 0" />
      <geometry>
        <mesh filename="../../meshes/r_foream.STL" />
      </geometry>
      <material name="">
        <color rgba="1 1 1 1" />
      </material>
    </visual>
  </link>
  <joint name="zarm_r4_joint" type="continuous">
    <origin xyz="0.0200000000000024 0 -0.2837" rpy="0 0 0" />
    <parent link="zarm_r3_link" />
    <child link="zarm_r4_link" />
    <axis xyz="0 1 0" />
    <limit lower="-2.44" upper="1.57" effort="100" velocity="100" />
  </joint>
  <transmission type="SimpleTransmission">
    <joint name="zarm_r4_joint"/>
    <actuator name="r_forearm_pitch_motor"/>
  </transmission>
  <link name="zarm_r5_link">
    <inertial>
      <origin xyz="-0.00129248 0.00018486 -0.05066688" rpy="0 0 0" />
      <mass value="0.61" />
      <inertia ixx="0.00031032" ixy="-1.07e-06" ixz="1.207e-05" iyy="0.00042573" iyz="9e-08" izz="0.00024678" />
    </inertial>
    <visual>
      <origin xyz="0 0 0" rpy="0 0 0" />
      <geometry>
        <mesh filename="../../meshes/r_hand_yaw.STL" />
      </geometry>
      <material name="">
        <color rgba="1 1 1 1" />
      </material>
    </visual>
  </link>
  <joint name="zarm_r5_joint" type="continuous">
    <origin xyz="-0.0200000000000001 0 -0.127037274261587" rpy="0 0 0" />
    <parent link="zarm_r4_link" />
    <child link="zarm_r5_link" />
    <axis xyz="0 0 1" />
    <limit lower="-1.657" upper="1.657" effort="100" velocity="100" />
  </joint>
  <transmission type="SimpleTransmission">
    <joint name="zarm_r5_joint"/>
    <actuator name="r_hand_yaw_motor"/>
  </transmission>
  <link name="zarm_r6_link">
    <inertial>
      <origin xyz="-0.0010068 -0.00161113 -0.01429861" rpy="0 0 0" />
      <mass value="0.331" />
      <inertia ixx="6.199e-05" ixy="-3.2e-07" ixz="-1.14e-06" iyy="7.103e-05" iyz="-5.9e-07" izz="7.741e-05" />
    </inertial>
    <visual>
      <origin xyz="0 0 0" rpy="0 0 0" />
      <geometry>
        <mesh filename="../../meshes/r_hand_roll.STL" />
      </geometry>
      <material name="">
        <color rgba="1 1 1 1" />
      </material>
    </visual>
  </link>
  <joint name="zarm_r6_joint" type="continuous">
    <origin xyz="0 0 -0.106462725738415" rpy="0 0 0" />
    <parent link="zarm_r5_link" />
    <child link="zarm_r6_link" />
    <axis xyz="1 0 0" />
    <limit lower="-1.57" upper="1.57" effort="100" velocity="100" />
  </joint>
    <transmission type="SimpleTransmission">
    <joint name="zarm_r6_joint"/>
    <actuator name="r_hand_pitch_motor"/>
  </transmission>
  <link name="zarm_r7_link">
    <inertial>
      <origin xyz="0.00137966 -0.01004189 -0.0920677" rpy="0 0 0" />
      <mass value="0.64" />
      <inertia ixx="0.00068969" ixy="1.481e-05" ixz="-1.878e-05" iyy="0.00068068" iyz="-4.898e-05" izz="0.00011994" />
    </inertial>
    <visual>
      <origin xyz="0 0 0" rpy="0 0 0" />
      <geometry>
        <mesh filename="../../meshes/r_hand_pitch.STL" />
      </geometry>
      <material name="">
        <color rgba="1 1 1 1" />
      </material>
    </visual>
  </link>
  <joint name="zarm_r7_joint" type="continuous">
    <origin xyz="0 0 -0.0209999999999999" rpy="0 0 0" />
    <parent link="zarm_r6_link" />
    <child link="zarm_r7_link" />
    <axis xyz="0 1 0" />
    <limit lower="-1.657" upper="1.657" effort="100" velocity="100" />
  </joint>
  <link name="zarm_r7_end_effector">
    <collision>
      <origin rpy="0 0 0" xyz="0 0 0" />
      <geometry>
        <sphere radius="0.005" />
      </geometry>
    </collision>
  </link>
  <joint name="zarm_r7_end_effector_joint" type="fixed">
    <origin xyz="0.0 0.03 -0.17" rpy="0 0 0" />
    <parent link="zarm_r7_link" />
    <child link="zarm_r7_end_effector" />
  </joint>
    <transmission type="SimpleTransmission">
    <joint name="zarm_r7_end_effector_joint"/>
    <actuator name="r_hand_roll_motor"/>
  </transmission>
  <!-- end frame -->
  <!-- <frame link="l_hand_pitch" name="l_hand_sole" xyz="0 0 -0.1" /> -->
  <!-- end frame -->
  <!-- <frame link="r_hand_pitch" name="r_hand_sole" xyz="0 0 -0.1" /> -->
</robot>

