<?xml version="1.0" encoding="utf-8"?>
<!-- This URDF was automatically created by SolidWorks to URDF Exporter! Originally created by Stephen Brawner (brawner@gmail.com) 
     Commit Version: 1.6.0-4-g7f85cfe  Build Version: 1.6.7995.38578
     For more information, please see http://wiki.ros.org/sw_urdf_exporter -->
<robot
  name="biped_s43">
  <link
    name="torso">
    <inertial>
      <origin
        xyz="-0.00152137308202996 6.570545971788E-05 0.180819231291639"
        rpy="0 0 0" />
      <mass
        value="8.00595696358141" />
      <inertia
        ixx="0.0420370417828757"
        ixy="-6.33819913200011E-06"
        ixz="0.000774581599267071"
        iyy="0.0246229225472557"
        iyz="-1.21865064780519E-06"
        izz="0.0339288066064417" />
    </inertial>
    <visual>
      <origin
        xyz="0 0 0"
        rpy="0 0 0" />
      <geometry>
        <mesh
          filename="package://biped_s43/meshes/torso.STL" />
      </geometry>
      <material
        name="">
        <color
          rgba="1 1 1 1" />
      </material>
    </visual>
    <collision>
      <origin
        xyz="0 0 0"
        rpy="0 0 0" />
      <geometry>
        <mesh
          filename="package://biped_s43/meshes/torso.STL" />
      </geometry>
    </collision>
  </link>
  <link
    name="r_arm_pitch">
    <inertial>
      <origin
        xyz="0.0142196704183039 0.015819769554607 0.00015144775718845"
        rpy="0 0 0" />
      <mass
        value="0.174747028375522" />
      <inertia
        ixx="0.0002659089458971"
        ixy="2.59598690021371E-05"
        ixz="-2.3385882920164E-07"
        iyy="0.000126276535014792"
        iyz="1.71632948801919E-06"
        izz="0.000192912111547749" />
    </inertial>
    <visual>
      <origin
        xyz="0 0 0"
        rpy="0 0 0" />
      <geometry>
        <mesh
          filename="package://biped_s43/meshes/r_arm_pitch.STL" />
      </geometry>
      <material
        name="">
        <color
          rgba="1 1 1 1" />
      </material>
    </visual>
    <collision>
      <origin
        xyz="0 0 0"
        rpy="0 0 0" />
      <geometry>
        <mesh
          filename="package://biped_s43/meshes/r_arm_pitch.STL" />
      </geometry>
    </collision>
  </link>
  <joint
    name="r_arm_pitch"
    type="revolute">
    <origin
      xyz="-0.0175 -0.2557 0.3245"
      rpy="0 0 0" />
    <parent
      link="torso" />
    <child
      link="r_arm_pitch" />
    <axis
      xyz="0 -1 0" />
    <limit
      lower="-1.047"
      upper="2.094"
      effort="0"
      velocity="0" />
  </joint>
  <link
    name="r_arm_roll">
    <inertial>
      <origin
        xyz="0.0328722861407201 1.50239842788835E-09 -0.033362001559319"
        rpy="0 0 0" />
      <mass
        value="0.0275279143681991" />
      <inertia
        ixx="2.18198697253185E-05"
        ixy="-1.05051355341662E-11"
        ixz="-6.54641028314625E-06"
        iyy="2.59041329678136E-05"
        iyz="6.42517523937707E-12"
        izz="1.33665922930808E-05" />
    </inertial>
    <visual>
      <origin
        xyz="0 0 0"
        rpy="0 0 0" />
      <geometry>
        <mesh
          filename="package://biped_s43/meshes/r_arm_roll.STL" />
      </geometry>
      <material
        name="">
        <color
          rgba="1 1 1 1" />
      </material>
    </visual>
    <collision>
      <origin
        xyz="0 0 0"
        rpy="0 0 0" />
      <geometry>
        <mesh
          filename="package://biped_s43/meshes/r_arm_roll.STL" />
      </geometry>
    </collision>
  </link>
  <joint
    name="r_arm_roll"
    type="revolute">
    <origin
      xyz="0 0 0"
      rpy="0 0 0" />
    <parent
      link="r_arm_pitch" />
    <child
      link="r_arm_roll" />
    <axis
      xyz="-1 0 0" />
    <limit
      lower="-0.349"
      upper="2.094"
      effort="0"
      velocity="0" />
  </joint>
  <link
    name="r_arm_yaw">
    <inertial>
      <origin
        xyz="0.00465923210128664 -0.00655492891218179 -0.150653535163084"
        rpy="0 0 0" />
      <mass
        value="0.173566237026" />
      <inertia
        ixx="0.000103216154072243"
        ixy="1.58660140392805E-08"
        ixz="6.17337468085342E-08"
        iyy="0.000126811315252261"
        iyz="-1.35227132861966E-05"
        izz="0.000101741106159027" />
    </inertial>
    <visual>
      <origin
        xyz="0 0 0"
        rpy="0 0 0" />
      <geometry>
        <mesh
          filename="package://biped_s43/meshes/r_arm_yaw.STL" />
      </geometry>
      <material
        name="">
        <color
          rgba="1 1 1 1" />
      </material>
    </visual>
    <collision>
      <origin
        xyz="0 0 0"
        rpy="0 0 0" />
      <geometry>
        <mesh
          filename="package://biped_s43/meshes/r_arm_yaw.STL" />
      </geometry>
    </collision>
  </link>
  <joint
    name="r_arm_yaw"
    type="revolute">
    <origin
      xyz="0 0 0"
      rpy="0 0 0" />
    <parent
      link="r_arm_roll" />
    <child
      link="r_arm_yaw" />
    <axis
      xyz="0 0 -1" />
    <limit
      lower="-1.57"
      upper="1.57"
      effort="0"
      velocity="0" />
  </joint>
  <link
    name="r_forearm_pitch">
    <inertial>
      <origin
        xyz="-2.65773622166489E-07 -0.023911354122526 -0.0401580148374924"
        rpy="0 0 0" />
      <mass
        value="0.0888093844950085" />
      <inertia
        ixx="8.27863367542845E-05"
        ixy="3.7066805249671E-11"
        ixz="-3.06429511692235E-10"
        iyy="6.87816672639171E-05"
        iyz="2.71271593806414E-05"
        izz="6.0740552391899E-05" />
    </inertial>
    <visual>
      <origin
        xyz="0 0 0"
        rpy="0 0 0" />
      <geometry>
        <mesh
          filename="package://biped_s43/meshes/r_forearm_pitch.STL" />
      </geometry>
      <material
        name="">
        <color
          rgba="0.898039215686275 0.917647058823529 0.929411764705882 1" />
      </material>
    </visual>
    <collision>
      <origin
        xyz="0 0 0"
        rpy="0 0 0" />
      <geometry>
        <mesh
          filename="package://biped_s43/meshes/r_forearm_pitch.STL" />
      </geometry>
    </collision>
  </link>
  <joint
    name="r_forearm_pitch"
    type="revolute">
    <origin
      xyz="0.0045067 0 -0.2046"
      rpy="0 0 0" />
    <parent
      link="r_arm_yaw" />
    <child
      link="r_forearm_pitch" />
    <axis
      xyz="0 1 0" />
    <limit
      lower="-1.57"
      upper="1.57"
      effort="0"
      velocity="0" />
  </joint>
  <link
    name="r_hand_yaw">
    <inertial>
      <origin
        xyz="-3.38870732800589E-05 -0.00597575931400085 0.0437739423349347"
        rpy="0 0 0" />
      <mass
        value="0.16829576540844" />
      <inertia
        ixx="8.41153559379105E-05"
        ixy="-1.58435297586044E-08"
        ixz="1.34228003156711E-08"
        iyy="0.000105118258005196"
        iyz="-9.65908626303867E-06"
        izz="9.72825471764427E-05" />
    </inertial>
    <visual>
      <origin
        xyz="0 0 0"
        rpy="0 0 0" />
      <geometry>
        <mesh
          filename="package://biped_s43/meshes/r_hand_yaw.STL" />
      </geometry>
      <material
        name="">
        <color
          rgba="1 1 1 1" />
      </material>
    </visual>
    <collision>
      <origin
        xyz="0 0 0"
        rpy="0 0 0" />
      <geometry>
        <mesh
          filename="package://biped_s43/meshes/r_hand_yaw.STL" />
      </geometry>
    </collision>
  </link>
  <joint
    name="r_hand_yaw"
    type="revolute">
    <origin
      xyz="0 0 -0.18915"
      rpy="0 0 0" />
    <parent
      link="r_forearm_pitch" />
    <child
      link="r_hand_yaw" />
    <axis
      xyz="0 0 -1" />
    <limit
      lower="-1.57"
      upper="1.57"
      effort="0"
      velocity="0" />
  </joint>
  <link
    name="r_hand_pitch">
    <inertial>
      <origin
        xyz="0.000855318718506226 -0.00213006893556911 -0.115813480423586"
        rpy="0 0 0" />
      <mass
        value="0.344320648555052" />
      <inertia
        ixx="0.000540956301757255"
        ixy="-5.77543528501418E-06"
        ixz="1.41402761249693E-05"
        iyy="0.00040279105474128"
        iyz="2.16236964612705E-05"
        izz="0.000201906090748558" />
    </inertial>
    <visual>
      <origin
        xyz="0 0 0"
        rpy="0 0 0" />
      <geometry>
        <mesh
          filename="package://biped_s43/meshes/r_hand_pitch.STL" />
      </geometry>
      <material
        name="">
        <color
          rgba="1 1 1 1" />
      </material>
    </visual>
    <collision>
      <origin
        xyz="0 0 0"
        rpy="0 0 0" />
      <geometry>
        <mesh
          filename="package://biped_s43/meshes/r_hand_pitch.STL" />
      </geometry>
    </collision>
  </link>
  <joint
    name="r_hand_pitch"
    type="revolute">
    <origin
      xyz="0 0 0"
      rpy="0 0 0" />
    <parent
      link="r_hand_yaw" />
    <child
      link="r_hand_pitch" />
    <axis
      xyz="0 1 0" />
    <limit
      lower="-1.396"
      upper="1.57"
      effort="0"
      velocity="0" />
  </joint>
  <link
    name="l_arm_pitch">
    <inertial>
      <origin
        xyz="0.0142197403011897 -0.0158198143370389 0.000151810457338808"
        rpy="0 0 0" />
      <mass
        value="0.174746585328354" />
      <inertia
        ixx="0.000265909520516632"
        ixy="-2.59598861144916E-05"
        ixz="-2.33624156891425E-07"
        iyy="0.000126272897577581"
        iyz="-1.7113334894126E-06"
        izz="0.000192916286448649" />
    </inertial>
    <visual>
      <origin
        xyz="0 0 0"
        rpy="0 0 0" />
      <geometry>
        <mesh
          filename="package://biped_s43/meshes/l_arm_pitch.STL" />
      </geometry>
      <material
        name="">
        <color
          rgba="1 1 1 1" />
      </material>
    </visual>
    <collision>
      <origin
        xyz="0 0 0"
        rpy="0 0 0" />
      <geometry>
        <mesh
          filename="package://biped_s43/meshes/l_arm_pitch.STL" />
      </geometry>
    </collision>
  </link>
  <joint
    name="l_arm_pitch"
    type="revolute">
    <origin
      xyz="-0.0175 0.2547 0.3245"
      rpy="0 0 0" />
    <parent
      link="torso" />
    <child
      link="l_arm_pitch" />
    <axis
      xyz="0 -1 0" />
    <limit
      lower="-1.047"
      upper="2.094"
      effort="0"
      velocity="0" />
  </joint>
  <link
    name="l_arm_roll">
    <inertial>
      <origin
        xyz="0.0328722823548324 -6.02081934308885E-09 -0.0333619980808738"
        rpy="0 0 0" />
      <mass
        value="0.0275279041732812" />
      <inertia
        ixx="2.18198673960488E-05"
        ixy="1.00434805014114E-11"
        ixz="-6.54641165117822E-06"
        iyy="2.59041339554032E-05"
        iyz="-7.19292827340807E-12"
        izz="1.33665916401548E-05" />
    </inertial>
    <visual>
      <origin
        xyz="0 0 0"
        rpy="0 0 0" />
      <geometry>
        <mesh
          filename="package://biped_s43/meshes/l_arm_roll.STL" />
      </geometry>
      <material
        name="">
        <color
          rgba="1 1 1 1" />
      </material>
    </visual>
    <collision>
      <origin
        xyz="0 0 0"
        rpy="0 0 0" />
      <geometry>
        <mesh
          filename="package://biped_s43/meshes/l_arm_roll.STL" />
      </geometry>
    </collision>
  </link>
  <joint
    name="l_arm_roll"
    type="revolute">
    <origin
      xyz="0 0 0"
      rpy="0 0 0" />
    <parent
      link="l_arm_pitch" />
    <child
      link="l_arm_roll" />
    <axis
      xyz="1 0 0" />
    <limit
      lower="-0.349"
      upper="2.094"
      effort="0"
      velocity="0" />
  </joint>
  <link
    name="l_arm_yaw">
    <inertial>
      <origin
        xyz="0.00435419486285331 0.00655494667807083 -0.150653532957614"
        rpy="0 0 0" />
      <mass
        value="0.173566136470917" />
      <inertia
        ixx="0.000103216153462413"
        ixy="1.58656474482053E-08"
        ixz="-6.17334881980063E-08"
        iyy="0.000126811314024844"
        iyz="1.35227132392023E-05"
        izz="0.000101741105051944" />
    </inertial>
    <visual>
      <origin
        xyz="0 0 0"
        rpy="0 0 0" />
      <geometry>
        <mesh
          filename="package://biped_s43/meshes/l_arm_yaw.STL" />
      </geometry>
      <material
        name="">
        <color
          rgba="1 1 1 1" />
      </material>
    </visual>
    <collision>
      <origin
        xyz="0 0 0"
        rpy="0 0 0" />
      <geometry>
        <mesh
          filename="package://biped_s43/meshes/l_arm_yaw.STL" />
      </geometry>
    </collision>
  </link>
  <joint
    name="l_arm_yaw"
    type="revolute">
    <origin
      xyz="0 0 0"
      rpy="0 0 0" />
    <parent
      link="l_arm_roll" />
    <child
      link="l_arm_yaw" />
    <axis
      xyz="0 0 -1" />
    <limit
      lower="-1.57"
      upper="1.57"
      effort="0"
      velocity="0" />
  </joint>
  <link
    name="l_forearm_pitch">
    <inertial>
      <origin
        xyz="2.65670778256885E-07 0.0239113540496901 -0.0401580149041652"
        rpy="0 0 0" />
      <mass
        value="0.0888093839871042" />
      <inertia
        ixx="8.27863365794365E-05"
        ixy="3.72014251093926E-11"
        ixz="3.06532124209034E-10"
        iyy="6.87816670177368E-05"
        iyz="-2.71271593158762E-05"
        izz="6.07405521072005E-05" />
    </inertial>
    <visual>
      <origin
        xyz="0 0 0"
        rpy="0 0 0" />
      <geometry>
        <mesh
          filename="package://biped_s43/meshes/l_forearm_pitch.STL" />
      </geometry>
      <material
        name="">
        <color
          rgba="0.898039215686275 0.917647058823529 0.929411764705882 1" />
      </material>
    </visual>
    <collision>
      <origin
        xyz="0 0 0"
        rpy="0 0 0" />
      <geometry>
        <mesh
          filename="package://biped_s43/meshes/l_forearm_pitch.STL" />
      </geometry>
    </collision>
  </link>
  <joint
    name="l_forearm_pitch"
    type="revolute">
    <origin
      xyz="0.0045067 0 -0.2046"
      rpy="0 0 0" />
    <parent
      link="l_arm_yaw" />
    <child
      link="l_forearm_pitch" />
    <axis
      xyz="0 -1 0" />
    <limit
      lower="-1.57"
      upper="1.57"
      effort="0"
      velocity="0" />
  </joint>
  <link
    name="l_hand_yaw">
    <inertial>
      <origin
        xyz="3.38916270049032E-05 0.00597576048894533 0.0437739462882778"
        rpy="0 0 0" />
      <mass
        value="0.168295683426251" />
      <inertia
        ixx="8.41153550451959E-05"
        ixy="-1.58432039717765E-08"
        ixz="-1.34226918791873E-08"
        iyy="0.000105118257522952"
        iyz="9.65908636117429E-06"
        izz="9.72825458729691E-05" />
    </inertial>
    <visual>
      <origin
        xyz="0 0 0"
        rpy="0 0 0" />
      <geometry>
        <mesh
          filename="package://biped_s43/meshes/l_hand_yaw.STL" />
      </geometry>
      <material
        name="">
        <color
          rgba="1 1 1 1" />
      </material>
    </visual>
    <collision>
      <origin
        xyz="0 0 0"
        rpy="0 0 0" />
      <geometry>
        <mesh
          filename="package://biped_s43/meshes/l_hand_yaw.STL" />
      </geometry>
    </collision>
  </link>
  <joint
    name="l_hand_yaw"
    type="revolute">
    <origin
      xyz="0 0 -0.18915"
      rpy="0 0 0" />
    <parent
      link="l_forearm_pitch" />
    <child
      link="l_hand_yaw" />
    <axis
      xyz="0 0 -1" />
    <limit
      lower="-1.57"
      upper="1.57"
      effort="0"
      velocity="0" />
  </joint>
  <link
    name="l_hand_pitch">
    <inertial>
      <origin
        xyz="0.000855309079931199 0.00213008600528963 -0.115813513460167"
        rpy="0 0 0" />
      <mass
        value="0.344320323618474" />
      <inertia
        ixx="0.000540955625710294"
        ixy="5.77541434372588E-06"
        ixz="1.4140308478252E-05"
        iyy="0.00040279053534777"
        iyz="-2.16239970470609E-05"
        izz="0.000201905906214185" />
    </inertial>
    <visual>
      <origin
        xyz="0 0 0"
        rpy="0 0 0" />
      <geometry>
        <mesh
          filename="package://biped_s43/meshes/l_hand_pitch.STL" />
      </geometry>
      <material
        name="">
        <color
          rgba="1 1 1 1" />
      </material>
    </visual>
    <collision>
      <origin
        xyz="0 0 0"
        rpy="0 0 0" />
      <geometry>
        <mesh
          filename="package://biped_s43/meshes/l_hand_pitch.STL" />
      </geometry>
    </collision>
  </link>
  <joint
    name="l_hand_pitch"
    type="revolute">
    <origin
      xyz="0 0 0"
      rpy="0 0 0" />
    <parent
      link="l_hand_yaw" />
    <child
      link="l_hand_pitch" />
    <axis
      xyz="0 1 0" />
    <limit
      lower="-1.396"
      upper="1.57"
      effort="0"
      velocity="0" />
  </joint>
</robot>