<?xml version="1.0" ?>
<!-- =================================================================================== -->
<!-- |    This document was autogenerated by xacro from /home/fandes/workspace/kuavo-ros-control/src/humanoid-control/humanoid_interface_drake/models/biped_gen4.0/urdf/biped_v3.xacro | -->
<!-- |    EDITING THIS FILE BY HAND IS NOT RECOMMENDED                                 | -->
<!-- =================================================================================== -->
<robot name="biped_v3" xmlns:drake="https://drake.mit.edu">
  <link name="torso">
    <inertial>
      <origin rpy="0 0 0" xyz="0.00383143 0.0 0.18350901"/>
      <mass value="35.0676395"/>
      <inertia ixx="0.95851611" ixy="0.00026968" ixz="0.06381351" iyy="0.83635568" iyz="0.00069789" izz="0.29474019"/>
    </inertial>
    <visual>
      <origin rpy="0 0 0" xyz="0 0 0"/>
      <geometry>
        <mesh filename="../../meshes/base_link.STL"/>
      </geometry>
      <material name="">
        <color rgba="0.43137 0.45098 0.43137 1"/>
      </material>
    </visual>
    <!-- <collision>
      <origin xyz="0 0 0" rpy="0 0 0" />
      <geometry>
        <mesh filename="../../meshes/base_link.STL" />
      </geometry>
    </collision> -->
  </link>
  <link name="l_leg_roll">
    <inertial>
      <origin rpy="0 0 0" xyz="0.06614234 -0.00000119 -0.00862806"/>
      <mass value="1.53800733"/>
      <inertia ixx="0.00189451" ixy="-0.00000100" ixz="-0.00010566" iyy="0.00282649" iyz="-0.00000006" izz="0.00366404"/>
    </inertial>
    <visual>
      <origin rpy="0 0 0" xyz="0 0 0"/>
      <geometry>
        <mesh filename="../../meshes/l_leg_roll.STL"/>
      </geometry>
      <material name="">
        <color rgba="0.6902 0.65882 0.63922 1"/>
      </material>
    </visual>
  </link>
  <joint name="l_leg_roll_joint" type="continuous">
    <origin rpy="0 0 0" xyz="-0.139 0.088087 -0.065549"/>
    <parent link="torso"/>
    <child link="l_leg_roll"/>
    <axis xyz="1 0 0"/>
    <limit effort="100" lower="-0.78" upper="1.57" velocity="25"/>
  </joint>
  <!--        ssss -->
  <transmission type="SimpleTransmission">
    <joint name="l_leg_roll_joint"/>
    <actuator name="l_leg_roll_motor"/>
  </transmission>
  <!-- sssssssss -->
  <link name="l_leg_yaw">
    <inertial>
      <origin rpy="0 0 0" xyz="0.00000000 0.04610400 -0.13256100"/>
      <mass value="1.60096700"/>
      <inertia ixx="0.00698359" ixy="0.00000237" ixz="-0.00000315" iyy="0.00460736" iyz="-0.00105143" izz="0.00482586"/>
    </inertial>
    <visual>
      <origin rpy="0 0 0" xyz="0 0 0"/>
      <geometry>
        <mesh filename="../../meshes/l_leg_yaw.STL"/>
      </geometry>
      <material name="">
        <color rgba="0.65098 0.61961 0.58824 1"/>
      </material>
    </visual>
  </link>
  <joint name="l_leg_yaw_joint" type="continuous">
    <origin rpy="0 0 0" xyz="0.1365 -0.0010866 -0.033901"/>
    <parent link="l_leg_roll"/>
    <child link="l_leg_yaw"/>
    <axis xyz="0 0 1"/>
    <limit effort="100" lower="-1.57" upper="1.57" velocity="25"/>
  </joint>
  <!--        ssss -->
  <transmission type="SimpleTransmission">
    <joint name="l_leg_yaw_joint"/>
    <actuator name="l_leg_yaw_motor"/>
  </transmission>
  <!-- sssssssss -->
  <link name="l_leg_pitch">
    <inertial>
      <origin rpy="0 0 0" xyz="-0.00644903 -0.09813560 -0.05357606"/>
      <mass value="2.46657100"/>
      <inertia ixx="0.02261778" ixy="-0.00007906" ixz="-0.00029350" iyy="0.02315672" iyz="-0.00182962" izz="0.00415881"/>
    </inertial>
    <visual>
      <origin rpy="0 0 0" xyz="0 0 0"/>
      <geometry>
        <mesh filename="../../meshes/l_leg_pitch.STL"/>
      </geometry>
      <material name="">
        <color rgba="0.52941 0.54902 0.54902 1"/>
      </material>
    </visual>
  </link>
  <joint name="l_leg_pitch_joint" type="continuous">
    <origin rpy="0 0 0" xyz="0 0.094 -0.09"/>
    <parent link="l_leg_yaw"/>
    <child link="l_leg_pitch"/>
    <axis xyz="0 1 0"/>
    <limit effort="100" lower="-2.35" upper="0.78" velocity="47"/>
  </joint>
  <!--        ssss -->
  <transmission type="SimpleTransmission">
    <joint name="l_leg_pitch_joint"/>
    <actuator name="l_leg_pitch_motor"/>
  </transmission>
  <!-- sssssssss -->
  <link name="l_knee">
    <inertial>
      <origin rpy="0 0 0" xyz="0.00080045 -0.00004225 -0.12049699"/>
      <mass value="1.62911554"/>
      <inertia ixx="0.01343597" ixy="-0.00000234" ixz="0.00020391" iyy="0.01359234" iyz="0.00018311" izz="0.00092149"/>
    </inertial>
    <visual>
      <origin rpy="0 0 0" xyz="0 0 0"/>
      <geometry>
        <mesh filename="../../meshes/l_knee.STL"/>
      </geometry>
      <material name="">
        <color rgba="0.68627 0.65882 0.63922 1"/>
      </material>
    </visual>
  </link>
  <joint name="l_knee_pitch_joint" type="revolute">
    <origin rpy="0 0 0" xyz="0.004136 -0.06635 -0.24997"/>
    <parent link="l_leg_pitch"/>
    <child link="l_knee"/>
    <axis xyz="0 1 0"/>
    <limit effort="100" lower="0.0" upper="2.61" velocity="47"/>
  </joint>
  <!--        ssss -->
  <transmission type="SimpleTransmission">
    <joint name="l_knee_pitch_joint"/>
    <actuator name="l_knee_pitch_motor"/>
  </transmission>
  <!-- sssssssss -->
  <link name="l_foot_pitch">
    <inertial>
      <origin rpy="0 0 0" xyz="0.00000000 -0.02099982 0"/>
      <mass value="0.05444454"/>
      <inertia ixx="0.00000411" ixy="0.00000000" ixz="0.00000000" iyy="0.00000411" iyz="0.00000000" izz="0.00000728"/>
    </inertial>
    <visual>
      <origin rpy="0 0 0" xyz="0 0 0"/>
      <geometry>
        <mesh filename="../../meshes/l_foot_pitch.STL"/>
      </geometry>
      <material name="">
        <color rgba="0.6902 0.65882 0.63922 1"/>
      </material>
    </visual>
  </link>
  <joint name="l_foot_pitch_joint" type="continuous">
    <origin rpy="0 0 0" xyz="0 -0.0022 -0.346"/>
    <parent link="l_knee"/>
    <child link="l_foot_pitch"/>
    <axis xyz="0 1 0"/>
    <limit effort="100" lower="-1.57" upper="1.57" velocity="25"/>
  </joint>
  <transmission type="SimpleTransmission">
    <joint name="l_foot_pitch_joint"/>
    <actuator name="l_foot_pitch_motor"/>
  </transmission>
  <!-- sssssssss -->
  <link name="l_foot_roll">
    <inertial>
      <origin rpy="0 0 0" xyz="-0.03594832 0.00000978 -0.02713029"/>
      <mass value="0.46707519"/>
      <inertia ixx="0.00040711" ixy="0.00000016" ixz="-0.00023147" iyy="0.00127525" iyz="-0.00000006" izz="0.00135360"/>
    </inertial>
    <visual>
      <origin rpy="0 0 0" xyz="0 0 0"/>
      <geometry>
        <mesh filename="../../meshes/l_foot_roll.STL"/>
      </geometry>
      <material name="">
        <color rgba="0.6902 0.65882 0.63922 1"/>
      </material>
    </visual>
    <visual>
      <origin rpy="0 0 0" xyz="-0.09 0.05 -0.0465"/>
      <geometry>
        <sphere radius="0.005"/>
      </geometry>
    </visual>
    <collision>
      <origin rpy="0 0 0" xyz="-0.09 0.05 -0.0465"/>
      <geometry>
        <sphere radius="0.005"/>
      </geometry>
    </collision>
    <visual>
      <origin rpy="0 0 0" xyz="-0.09 -0.05 -0.0465"/>
      <geometry>
        <sphere radius="0.005"/>
      </geometry>
    </visual>
    <collision>
      <origin rpy="0 0 0" xyz="-0.09 -0.05 -0.0465"/>
      <geometry>
        <sphere radius="0.005"/>
      </geometry>
    </collision>
    <visual>
      <origin rpy="0 0 0" xyz="0.15 0.05 -0.0465"/>
      <geometry>
        <sphere radius="0.005"/>
      </geometry>
    </visual>
    <collision>
      <origin rpy="0 0 0" xyz="0.15 0.05 -0.0465"/>
      <geometry>
        <sphere radius="0.005"/>
      </geometry>
    </collision>
    <visual>
      <origin rpy="0 0 0" xyz="0.15 -0.05 -0.0465"/>
      <geometry>
        <sphere radius="0.005"/>
      </geometry>
    </visual>
    <collision>
      <origin rpy="0 0 0" xyz="0.15 -0.05 -0.0465"/>
      <geometry>
        <sphere radius="0.005"/>
      </geometry>
    </collision>
  </link>
  <joint name="l_foot_roll_joint" type="continuous">
    <origin rpy="0 0 0" xyz="0 0 0"/>
    <parent link="l_foot_pitch"/>
    <child link="l_foot_roll"/>
    <axis xyz="1 0 0"/>
    <limit effort="100" lower="-1.39" upper="0.78" velocity="25"/>
  </joint>
  <transmission type="SimpleTransmission">
    <joint name="l_foot_roll_joint"/>
    <actuator name="l_foot_roll_motor"/>
  </transmission>
  <!-- sssssssss -->
  <frame link="l_foot_roll" name="l_foot_sole" xyz="0.03 0.0 -0.0465"/>
  <frame link="l_foot_roll" name="l_foot_toe" xyz="0.15 0.0 -0.0465"/>
  <frame link="l_foot_roll" name="l_foot_heel" xyz="-0.09 0.0 -0.0465"/>
  <link name="r_leg_roll">
    <inertial>
      <origin rpy="0 0 0" xyz="0.06614233 0.00000119 -0.00862806"/>
      <mass value="1.53800714"/>
      <inertia ixx="0.00189451" ixy="0.00000100" ixz="-0.00010566" iyy="0.00282648" iyz="0.00000006" izz="0.00366404"/>
    </inertial>
    <visual>
      <origin rpy="0 0 0" xyz="0 0 0"/>
      <geometry>
        <mesh filename="../../meshes/r_leg_roll.STL"/>
      </geometry>
      <material name="">
        <color rgba="0.6902 0.65882 0.63922 1"/>
      </material>
    </visual>
  </link>
  <joint name="r_leg_roll_joint" type="continuous">
    <origin rpy="0 0 0" xyz="-0.139 -0.088087 -0.065549"/>
    <parent link="torso"/>
    <child link="r_leg_roll"/>
    <axis xyz="1 0 0"/>
    <limit effort="100" lower="-1.57" upper="0.78" velocity="25"/>
  </joint>
  <!--        ssss -->
  <transmission type="SimpleTransmission">
    <joint name="r_leg_roll_joint"/>
    <actuator name="r_leg_roll_motor"/>
  </transmission>
  <!-- sssssssss -->
  <link name="r_leg_yaw">
    <inertial>
      <origin rpy="0 0 0" xyz="0.00004661 -0.04610359 -0.13257364"/>
      <mass value="1.60096695"/>
      <inertia ixx="0.00520439" ixy="-0.00000302" ixz="-0.00000372" iyy="0.00397740" iyz="0.00063198" izz="0.00391648"/>
    </inertial>
    <visual>
      <origin rpy="0 0 0" xyz="0 0 0"/>
      <geometry>
        <mesh filename="../../meshes/r_leg_yaw.STL"/>
      </geometry>
      <material name="">
        <color rgba="0.650980392156863 0.619607843137255 0.588235294117647 1"/>
      </material>
    </visual>
  </link>
  <joint name="r_leg_yaw_joint" type="continuous">
    <origin rpy="0 0 0" xyz="0.1365 0.0010866 -0.033901"/>
    <parent link="r_leg_roll"/>
    <child link="r_leg_yaw"/>
    <axis xyz="0 0 1"/>
    <limit effort="100" lower="-1.57" upper="1.57" velocity="25"/>
  </joint>
  <!--        ssss -->
  <transmission type="SimpleTransmission">
    <joint name="r_leg_yaw_joint"/>
    <actuator name="r_leg_yaw_motor"/>
  </transmission>
  <!-- sssssssss -->
  <link name="r_leg_pitch">
    <inertial>
      <origin rpy="0 0 0" xyz="-0.00644903 0.09813560 -0.05357606"/>
      <mass value="2.46657141"/>
      <inertia ixx="0.02254838" ixy="0.00023457" ixz="0.00013808" iyy="0.02319666" iyz="0.00259984" izz="0.00432904"/>
    </inertial>
    <visual>
      <origin rpy="0 0 0" xyz="0 0 0"/>
      <geometry>
        <mesh filename="../../meshes/r_leg_pitch.STL"/>
      </geometry>
      <material name="">
        <color rgba="0.529411764705882 0.549019607843137 0.549019607843137 1"/>
      </material>
    </visual>
  </link>
  <joint name="r_leg_pitch_joint" type="continuous">
    <origin rpy="0 0 0" xyz="0 -0.094 -0.09"/>
    <parent link="r_leg_yaw"/>
    <child link="r_leg_pitch"/>
    <axis xyz="0 1 0"/>
    <limit effort="100" lower="-2.35" upper="0.78" velocity="47"/>
  </joint>
  <!--        ssss -->
  <transmission type="SimpleTransmission">
    <joint name="r_leg_pitch_joint"/>
    <actuator name="r_leg_pitch_motor"/>
  </transmission>
  <!-- sssssssss -->
  <link name="r_knee">
    <inertial>
      <origin rpy="0 0 0" xyz="0.00080045 0.00004225 -0.12049699"/>
      <mass value="1.62911540"/>
      <inertia ixx="0.01343597" ixy="0.00000234" ixz="0.00020391" iyy="0.01359234" iyz="-0.00018311" izz="0.00092149"/>
    </inertial>
    <visual>
      <origin rpy="0 0 0" xyz="0 0 0"/>
      <geometry>
        <mesh filename="../../meshes/r_knee.STL"/>
      </geometry>
      <material name="">
        <color rgba="0.686274509803922 0.658823529411765 0.63921568627451 1"/>
      </material>
    </visual>
  </link>
  <joint name="r_knee_pitch_joint" type="revolute">
    <origin rpy="0 0 0" xyz="0.004136 0.06635 -0.24997"/>
    <parent link="r_leg_pitch"/>
    <child link="r_knee"/>
    <axis xyz="0 1 0"/>
    <limit effort="100" lower="0.0" upper="2.61" velocity="47"/>
  </joint>
  <!--        ssss -->
  <transmission type="SimpleTransmission">
    <joint name="r_knee_pitch_joint"/>
    <actuator name="r_knee_pitch_motor"/>
  </transmission>
  <!-- sssssssss -->
  <link name="r_foot_pitch">
    <inertial>
      <origin rpy="0 0 0" xyz="0 0.02100018 0"/>
      <mass value="0.05444454"/>
      <inertia ixx="0.00000411" ixy="0" ixz="0" iyy="0.00000411" iyz="0" izz="0.00000728"/>
    </inertial>
    <visual>
      <origin rpy="0 0 0" xyz="0 0 0"/>
      <geometry>
        <mesh filename="../../meshes/r_foot_pitch.STL"/>
      </geometry>
      <material name="">
        <color rgba="0.690196078431373 0.658823529411765 0.63921568627451 1"/>
      </material>
    </visual>
  </link>
  <joint name="r_foot_pitch_joint" type="continuous">
    <origin rpy="0 0 0" xyz="0 0.0022 -0.346"/>
    <parent link="r_knee"/>
    <child link="r_foot_pitch"/>
    <axis xyz="0 1 0"/>
    <limit effort="100" lower="-1.57" upper="1.57" velocity="25"/>
  </joint>
  <!--        ssss -->
  <transmission type="SimpleTransmission">
    <joint name="r_foot_pitch_joint"/>
    <actuator name="r_foot_pitch_motor"/>
  </transmission>
  <!-- sssssssss -->
  <link name="r_foot_roll">
    <inertial>
      <origin rpy="0 0 0" xyz="-0.03594837 -0.00000972 -0.02713025"/>
      <mass value="0.46707428"/>
      <inertia ixx="0.00040710" ixy="-0.00000016" ixz="-0.00023147" iyy="0.00127525" iyz="0.00000006" izz="0.00135359"/>
    </inertial>
    <visual>
      <origin rpy="0 0 0" xyz="0 0 0"/>
      <geometry>
        <mesh filename="../../meshes/r_foot_roll.STL"/>
      </geometry>
      <material name="">
        <color rgba="0.690196078431373 0.658823529411765 0.63921568627451 1"/>
      </material>
    </visual>
    <visual>
      <origin rpy="0 0 0" xyz="-0.09 0.05 -0.0465"/>
      <geometry>
        <sphere radius="0.005"/>
      </geometry>
    </visual>
    <collision>
      <origin rpy="0 0 0" xyz="-0.09 0.05 -0.0465"/>
      <geometry>
        <sphere radius="0.005"/>
      </geometry>
    </collision>
    <visual>
      <origin rpy="0 0 0" xyz="-0.09 -0.05 -0.0465"/>
      <geometry>
        <sphere radius="0.005"/>
      </geometry>
    </visual>
    <collision>
      <origin rpy="0 0 0" xyz="-0.09 -0.05 -0.0465"/>
      <geometry>
        <sphere radius="0.005"/>
      </geometry>
    </collision>
    <visual>
      <origin rpy="0 0 0" xyz="0.15 0.05 -0.0465"/>
      <geometry>
        <sphere radius="0.005"/>
      </geometry>
    </visual>
    <collision>
      <origin rpy="0 0 0" xyz="0.15 0.05 -0.0465"/>
      <geometry>
        <sphere radius="0.005"/>
      </geometry>
    </collision>
    <visual>
      <origin rpy="0 0 0" xyz="0.15 -0.05 -0.0465"/>
      <geometry>
        <sphere radius="0.005"/>
      </geometry>
    </visual>
    <collision>
      <origin rpy="0 0 0" xyz="0.15 -0.05 -0.0465"/>
      <geometry>
        <sphere radius="0.005"/>
      </geometry>
    </collision>
  </link>
  <joint name="r_foot_roll_joint" type="continuous">
    <origin rpy="0 0 0" xyz="0 0 0"/>
    <parent link="r_foot_pitch"/>
    <child link="r_foot_roll"/>
    <axis xyz="1 0 0"/>
    <limit effort="100" lower="-1.39" upper="0.78" velocity="25"/>
  </joint>
  <!--        ssss -->
  <transmission type="SimpleTransmission">
    <joint name="r_foot_roll_joint"/>
    <actuator name="r_foot_roll_motor"/>
  </transmission>
  <!-- sssssssss -->
  <frame link="r_foot_roll" name="r_foot_sole" xyz="0.03 -0.0 -0.0465"/>
  <frame link="r_foot_roll" name="r_foot_toe" xyz="0.15 -0.0 -0.0465"/>
  <frame link="r_foot_roll" name="r_foot_heel" xyz="-0.09 -0.0 -0.0465"/>
</robot>

