<?xml version="1.0" encoding="utf-8"?>
<!-- This URDF was automatically created by SolidWorks to URDF Exporter! Originally created by
Stephen Brawner (brawner@gmail.com) 
     Commit Version: 1.6.0-4-g7f85cfe  Build Version: 1.6.7995.38578
     For more information, please see http://wiki.ros.org/sw_urdf_exporter -->
<robot name="biped_s4">
  <mujoco>
    <compiler meshdir="../meshes/" balanceinertia="true" discardvisual="false"/>
  </mujoco>
  <link name="dummy_link">
  </link>
  <link name="base_link">
    <inertial>
      <origin 
        xyz="0.00383143 0.0 0.18350901"
      	rpy="0 0 0" />
      <mass 
        value="26.40313"  />
      <inertia ixx="0.95851611" ixy="0.00026968" ixz="0.06381351" iyy="0.83635568" iyz="0.00069789" izz="0.29474019" />
    </inertial>
    <visual>
      <origin 
        xyz="0 0 0"
        rpy="0 0 0" />
      <geometry>
        <mesh filename="package://kuavo_assets/models/biped_s40/meshes/torso.obj" />
      </geometry>
      <material 
        name="">
        <color 
          rgba="1 1 1 1" />
      </material>
    </visual>
  </link>
  <joint name="dummy_to_base_link" type="fixed">
    <parent link="dummy_link"/>
    <child link="base_link"/>
    <origin rpy="0 0 0" xyz="0 0 0"/>
  </joint>

  <link name="leg_l1_link">
    <inertial>
      <origin 
        xyz="0.06614234 -0.00000119 -0.00862806"
        rpy="0 0 0" />
      <mass 
        value="1.53800733"
      />
      <inertia 
        ixx="0.00189451"
        ixy="-0.00000100"
        ixz="-0.00010566"
        iyy="0.00282649"
        iyz="-0.00000006"
        izz="0.00366404" />
    </inertial>
    <visual>
      <origin 
        xyz="0 0 0"
        rpy="0 0 0" />
      <geometry>
        <mesh filename="package://kuavo_assets/models/biped_s40/meshes/l_leg_roll.obj" />
      </geometry>
      <material 
        name="">
        <color 
          rgba="0.6902 0.65882 0.63922 1" />
      </material>
    </visual>
  </link>
  <joint 
    name="leg_l1_joint"
    type="revolute">
    <origin 
      xyz="-0.139 0.088087 -0.065549"
      rpy="0 0 0" />
    <parent 
      link="base_link" />
    <child 
      link="leg_l1_link" />
    <axis 
      xyz="1 0 0" />
    <limit
      lower="-0.31"
      upper="0.66"
      effort="85"
      velocity="14" />
  </joint>

  <link 
    name="leg_l2_link">
    <inertial>
      <origin 
        xyz="0.00000000 0.04610400 -0.13256100"
        rpy="0 0 0" />
      <mass 
        value="1.60096700"/>
      <inertia 
        ixx="0.00698359"
        ixy="0.00000237"
        ixz="-0.00000315"
        iyy="0.00460736"
        iyz="-0.00105143"
        izz="0.00482586" />
    </inertial>
    <visual>
      <origin 
        xyz="0 0 0"
        rpy="0 0 0" />
      <geometry>
        <mesh filename="package://kuavo_assets/models/biped_s40/meshes/l_leg_yaw.obj" />
      </geometry>
      <material 
        name="">
        <color rgba="0.65098 0.61961 0.58824 1" />
      </material>
    </visual>
  </link>
  <joint name="leg_l2_joint"
    type="revolute">
    <origin 
      xyz="0.1365 -0.0010866 -0.033901"
      rpy="0 0 0" />
    <parent 
      link="leg_l1_link" />
    <child 
      link="leg_l2_link" />
    <axis 
      xyz="0 0 1" />
    <limit
      lower="-0.52"
      upper="1.04"
      effort="60"
      velocity="14" />
  </joint>

  <link name="leg_l3_link">
    <inertial>
      <origin 
        xyz="-0.00644903 -0.09813560 -0.05357606"
        rpy="0 0 0" />
      <mass 
        value="2.46657100"/>
      <inertia 
        ixx="0.02261778"
        ixy="-0.00007906"
        ixz="-0.00029350"
        iyy="0.02315672"
        iyz="-0.00182962"
        izz="0.00415881" />
    </inertial>
    <visual>
      <origin 
        xyz="0 0 0"
        rpy="0 0 0" />
      <geometry>
        <mesh 
          filename="package://kuavo_assets/models/biped_s40/meshes/l_leg_pitch.obj" />
      </geometry>
      <material 
        name="">
        <color 
          rgba="0.52941 0.54902 0.54902 1" />
      </material>
    </visual>
  </link>
  <joint 
    name="leg_l3_joint"
    type="revolute">
    <origin 
      xyz="0 0.094 -0.09"
      rpy="0 0 0" />
    <parent 
      link="leg_l2_link" />
    <child 
      link="leg_l3_link" />
    <axis 
      xyz="0 1 0" />
    <limit
      lower="-1.83"
      upper="1.04"
      effort="85"
      velocity="14" />
  </joint>

  <link name="leg_l4_link">
    <inertial>
      <origin 
        xyz="0.00080045 -0.00004225 -0.12049699"
        rpy="0 0 0" />
      <mass 
        value="1.62911554" />
      <inertia 
        ixx="0.01343597"
        ixy="-0.00000234"
        ixz="0.00020391"
        iyy="0.01359234"
        iyz="0.00018311"
        izz="0.00092149" />
    </inertial>
    <visual>
      <origin 
        xyz="0 0 0"
        rpy="0 0 0" />
      <geometry>
        <mesh 
          filename="package://kuavo_assets/models/biped_s40/meshes/l_knee.obj" />
      </geometry>
      <material 
        name="">
        <color rgba="0.68627 0.65882 0.63922 1" />
      </material>
    </visual>
  </link>
  <joint name="leg_l4_joint"
    type="revolute">
    <origin 
      xyz="0.004136 -0.06635 -0.24997"
      rpy="0 0 0" />
    <parent 
      link="leg_l3_link" />
    <child 
      link="leg_l4_link" />
    <axis 
      xyz="0 1 0" />
    <limit
      lower="-0.0"
      upper="2.18"
      effort="85"
      velocity="14" />
  </joint>

  <link name="leg_l5_link">
    <inertial>
      <origin 
        xyz="0.00000000 -0.02099982 0"
        rpy="0 0 0" />
      <mass 
        value="0.05444454" />
      <inertia 
        ixx="0.00000411"
        ixy="0.00000000"
        ixz="0.00000000"
        iyy="0.00000411"
        iyz="0.00000000"
        izz="0.00000728" />
    </inertial>
    <visual>
      <origin 
        xyz="0 0 0"
        rpy="0 0 0" />
      <geometry>
        <mesh filename="package://kuavo_assets/models/biped_s40/meshes/l_foot_pitch.obj" />
      </geometry>
      <material name="">
        <color rgba="0.6902 0.65882 0.63922 1" />
      </material>
    </visual>
  </link>
  <joint 
    name="leg_l5_joint"
    type="revolute">
    <origin 
      xyz="0 -0.0022 -0.346"
      rpy="0 0 0" />
    <parent 
      link="leg_l4_link" />
    <child 
      link="leg_l5_link" />
    <axis 
      xyz="0 1 0" />
    <limit
      lower="-0.61"
      upper="0.52"
      effort="36"
      velocity="14" />
  </joint>

  <link name="leg_l6_link">
    <inertial>
      <origin 
        xyz="-0.03594832 0.00000978 -0.02713029"
        rpy="0 0 0" />
      <mass 
        value="0.46707519" />
      <inertia 
        ixx="0.00040711"
        ixy="0.00000016"
        ixz="-0.00023147"
        iyy="0.00127525"
        iyz="-0.00000006"
        izz="0.00135360" />
    </inertial>
    <visual>
      <origin 
        xyz="0 0 0"
        rpy="0 0 0" />
      <geometry>
        <mesh filename="package://kuavo_assets/models/biped_s40/meshes/l_foot_roll.obj" />
      </geometry>
      <material 
        name="">
        <color 
          rgba="0.6902 0.65882 0.63922 1" />
      </material>
    </visual>
    <visual>
      <origin rpy="0 0 0" xyz="-0.09 0.05 -0.0465" />
      <geometry>
        <sphere radius="0.005" />
      </geometry>
    </visual>
    <collision>
      <origin rpy="0 0 0" xyz="-0.09 0.05 -0.0465" />
      <geometry>
        <sphere radius="0.005" />
      </geometry>
    </collision>
    <visual>
      <origin rpy="0 0 0" xyz="-0.09 -0.05 -0.0465" />
      <geometry>
        <sphere radius="0.005" />
      </geometry>
    </visual>
    <collision>
      <origin rpy="0 0 0" xyz="-0.09 -0.05 -0.0465" />
      <geometry>
        <sphere radius="0.005" />
      </geometry>
    </collision>
    <visual>
      <origin rpy="0 0 0" xyz="0.15 0.05 -0.0465" />
      <geometry>
        <sphere radius="0.005" />
      </geometry>
    </visual>
    <collision>
      <origin rpy="0 0 0" xyz="0.15 0.05 -0.0465" />
      <geometry>
        <sphere radius="0.005" />
      </geometry>
    </collision>
    <visual>
      <origin rpy="0 0 0" xyz="0.15 -0.05 -0.0465" />
      <geometry>
        <sphere radius="0.005" />
      </geometry>
    </visual>
    <collision>
      <origin rpy="0 0 0" xyz="0.15 -0.05 -0.0465" />
      <geometry>
        <sphere radius="0.005" />
      </geometry>
    </collision>
  </link>
  <joint 
    name="leg_l6_joint"
    type="revolute">
    <origin 
      xyz="0 0 0"
      rpy="0 0 0" />
    <parent 
      link="leg_l5_link" />
    <child 
      link="leg_l6_link" />
    <axis 
      xyz="1 0 0" />
    <limit
      lower="-0.61"
      upper="0.52"
      effort="36"
      velocity="14" />
  </joint>

  <link 
    name="ll_foot_toe">
    <collision>
      <origin 
        rpy="0 0 0"
        xyz="0 0 0"/>
      <geometry>
        <sphere radius="0.005"/>
      </geometry>
    </collision>
  </link>
  <joint name="ll_foot_toe_joint"
    type="fixed">
    <origin 
      xyz="0.15 0.05 -0.0465"
      rpy="0 0 0" />
    <parent 
      link="leg_l6_link" />
    <child 
      link="ll_foot_toe" />
  </joint>
  <link name="ll_foot_heel">
    <collision>
      <origin 
        rpy="0 0 0"
        xyz="0 0 0"/>
      <geometry>
        <sphere radius="0.005"/>
      </geometry>
    </collision>
  </link>
  <joint 
    name="ll_foot_heel_joint"
    type="fixed">
    <origin 
      xyz="-0.09 0.05 -0.0465"
      rpy="0 0 0" />
    <parent link="leg_l6_link" />
    <child link="ll_foot_heel" />
  </joint>

  <link name="lr_foot_toe">
    <collision>
      <origin 
        rpy="0 0 0"
        xyz="0 0 0"/>
      <geometry>
        <sphere radius="0.005"/>
      </geometry>
    </collision>
  </link>
  <joint 
    name="lr_foot_toe_joint"
    type="fixed">
    <origin 
      xyz="0.15 -0.05 -0.0465"
      rpy="0 0 0" />
    <parent 
      link="leg_l6_link" />
    <child 
      link="lr_foot_toe" />
  </joint>
  <link 
    name="lr_foot_heel">
    <collision>
      <origin 
        rpy="0 0 0"
        xyz="0 0 0"/>
      <geometry>
        <sphere radius="0.005"/>
      </geometry>
    </collision>
  </link>
  <joint 
    name="lr_foot_heel_joint"
    type="fixed">
    <origin 
      xyz="-0.09 -0.05 -0.0465"
      rpy="0 0 0" />
    <parent 
      link="leg_l6_link" />
    <child 
      link="lr_foot_heel" />
  </joint>
  <link name="l_foot_toe">
    <collision>
      <origin 
        rpy="0 0 0"
        xyz="0 0 0"/>
      <geometry>
        <sphere radius="0.005"/>
      </geometry>
    </collision>
  </link>
  <joint 
    name="l_foot_toe_joint"
    type="fixed">
    <origin 
      xyz="0.15 0.0 -0.0465"
      rpy="0 0 0" />
    <parent 
      link="leg_l6_link" />
    <child 
      link="l_foot_toe" />
  </joint>
  <link name="l_foot_heel">
    <collision>
      <origin 
        rpy="0 0 0"
        xyz="0 0 0"/>
      <geometry>
        <sphere radius="0.005"/>
      </geometry>
    </collision>
  </link>
  <joint 
    name="l_foot_heel_joint"
    type="fixed">
    <origin xyz="-0.09 0.0 -0.0465"
      rpy="0 0 0" />
    <parent 
      link="leg_l6_link" />
    <child 
      link="l_foot_heel" />
  </joint>

  <link 
    name="leg_r1_link">
    <inertial>
      <origin 
        xyz="0.06614233 0.00000119 -0.00862806"
        rpy="0 0 0" />
      <mass 
        value="1.53800714" />
      <inertia 
        ixx="0.00189451"
        ixy="0.00000100"
        ixz="-0.00010566"
        iyy="0.00282648"
        iyz="0.00000006"
        izz="0.00366404" />
    </inertial>
    <visual>
      <origin 
        xyz="0 0 0"
        rpy="0 0 0" />
      <geometry>
        <mesh filename="package://kuavo_assets/models/biped_s40/meshes/r_leg_roll.obj" />
      </geometry>
      <material 
        name="">
        <color rgba="0.6902 0.65882 0.63922 1" />
      </material>
    </visual>
  </link>
  <joint name="leg_r1_joint"
    type="revolute">
    <origin 
      xyz="-0.139 -0.088087 -0.065549"
      rpy="0 0 0" />
    <parent 
      link="base_link" />
    <child 
      link="leg_r1_link" />
    <axis 
      xyz="1 0 0" />
    <limit
      lower="-0.6629"
      upper="0.314"
      effort="85"
      velocity="14" />
  </joint>

  <link name="leg_r2_link">
    <inertial>
      <origin 
        xyz="0.00004661 -0.04610359 -0.13257364"
        rpy="0 0 0" />
      <mass 
        value="1.60096695" />
      <inertia 
        ixx="0.00520439"
        ixy="-0.00000302"
        ixz="-0.00000372"
        iyy="0.00397740"
        iyz="0.00063198"
        izz="0.00391648" />
    </inertial>
    <visual>
      <origin 
        xyz="0 0 0"
        rpy="0 0 0" />
      <geometry>
        <mesh filename="package://kuavo_assets/models/biped_s40/meshes/r_leg_yaw.obj" />
      </geometry>
      <material 
        name="">
        <color 
          rgba="0.650980392156863 0.619607843137255 0.588235294117647 1" />
      </material>
    </visual>
  </link>
  <joint 
    name="leg_r2_joint"
    type="revolute">
    <origin 
      xyz="0.1365 0.0010866 -0.033901"
      rpy="0 0 0" />
    <parent 
      link="leg_r1_link" />
    <child 
      link="leg_r2_link" />
    <axis 
      xyz="0 0 1" />
    <limit
      lower="-1.04"
      upper="0.52"
      effort="60"
      velocity="14" />
  </joint>

  <link name="leg_r3_link">
    <inertial>
      <origin 
        xyz="-0.00644903 0.09813560 -0.05357606"
        rpy="0 0 0" />
      <mass 
        value="2.46657141"/>
      <inertia 
        ixx="0.02254838"
        ixy="0.00023457"
        ixz="0.00013808"
        iyy="0.02319666"
        iyz="0.00259984"
        izz="0.00432904" />
    </inertial>
    <visual>
      <origin 
        xyz="0 0 0"
        rpy="0 0 0" />
      <geometry>
        <mesh filename="package://kuavo_assets/models/biped_s40/meshes/r_leg_pitch.obj" />
      </geometry>
      <material 
        name="">
        <color 
          rgba="0.529411764705882 0.549019607843137 0.549019607843137 1" />
      </material>
    </visual>
  </link>
  <joint name="leg_r3_joint"
    type="revolute">
    <origin 
      xyz="0 -0.094 -0.09"
      rpy="0 0 0" />
    <parent 
      link="leg_r2_link" />
    <child 
      link="leg_r3_link" />
    <axis xyz="0 1 0" />
    <limit
      lower="-1.83"
      upper="1.04"
      effort="85"
      velocity="14" />
  </joint>

  <link name="leg_r4_link">
    <inertial>
      <origin 
        xyz="0.00080045 0.00004225 -0.12049699"
        rpy="0 0 0" />
      <mass 
        value="1.62911540" />
      <inertia 
        ixx="0.01343597"
        ixy="0.00000234"
        ixz="0.00020391"
        iyy="0.01359234"
        iyz="-0.00018311"
        izz="0.00092149" />
    </inertial>
    <visual>
      <origin 
        xyz="0 0 0"
        rpy="0 0 0" />
      <geometry>
        <mesh 
          filename="package://kuavo_assets/models/biped_s40/meshes/r_knee.obj" />
      </geometry>
      <material 
        name="">
        <color 
          rgba="0.686274509803922 0.658823529411765 0.63921568627451 1" />
      </material>
    </visual>
  </link>
  <joint 
    name="leg_r4_joint"
    type="revolute">
    <origin 
      xyz="0.004136 0.06635 -0.24997"
      rpy="0 0 0" />
    <parent 
      link="leg_r3_link" />
    <child 
      link="leg_r4_link" />
    <axis 
      xyz="0 1 0" />
    <limit
      lower="-0.0"
      upper="2.18"
      effort="85"
      velocity="14" />
  </joint>

  <link name="leg_r5_link">
    <inertial>
      <origin 
        xyz="0 0.02100018 0"
        rpy="0 0 0" />
      <mass 
        value="0.05444454"/>
      <inertia 
        ixx="0.00000411"
        ixy="0"
        ixz="0"
        iyy="0.00000411"
        iyz="0"
        izz="0.00000728"/>
    </inertial>
    <visual>
      <origin 
        xyz="0 0 0"
        rpy="0 0 0" />
      <geometry>
        <mesh 
          filename="package://kuavo_assets/models/biped_s40/meshes/r_foot_pitch.obj" />
      </geometry>
      <material 
        name="">
        <color rgba="0.690196078431373 0.658823529411765 0.63921568627451 1" />
      </material>
    </visual>
  </link>
  <joint name="leg_r5_joint"
    type="revolute">
    <origin 
      xyz="0 0.0022 -0.346"
      rpy="0 0 0" />
    <parent 
      link="leg_r4_link" />
    <child 
      link="leg_r5_link" />
    <axis 
      xyz="0 1 0" />
    <limit
      lower="-0.61"
      upper="0.52"
      effort="36"
      velocity="14" />
  </joint>

  <link name="leg_r6_link">
    <inertial>
      <origin 
        xyz="-0.03594837 -0.00000972 -0.02713025"
        rpy="0 0 0" />
      <mass 
        value="0.46707428" />
      <inertia 
        ixx="0.00040710"
        ixy="-0.00000016"
        ixz="-0.00023147"
        iyy="0.00127525"
        iyz="0.00000006"
        izz="0.00135359" />
    </inertial>
    <visual>
      <origin 
        xyz="0 0 0"
        rpy="0 0 0" />
      <geometry>
        <mesh 
          filename="package://kuavo_assets/models/biped_s40/meshes/r_foot_roll.obj" />
      </geometry>
      <material 
        name="">
        <color 
          rgba="0.690196078431373 0.658823529411765 0.63921568627451 1" />
      </material>
    </visual>
    <visual>
      <origin rpy="0 0 0" xyz="-0.09 0.05 -0.0465" />
      <geometry>
        <sphere radius="0.005" />
      </geometry>
    </visual>
    <collision>
      <origin rpy="0 0 0" xyz="-0.09 0.05 -0.0465" />
      <geometry>
        <sphere radius="0.005" />
      </geometry>
    </collision>
    <visual>
      <origin rpy="0 0 0" xyz="-0.09 -0.05 -0.0465" />
      <geometry>
        <sphere radius="0.005" />
      </geometry>
    </visual>
    <collision>
      <origin rpy="0 0 0" xyz="-0.09 -0.05 -0.0465" />
      <geometry>
        <sphere radius="0.005" />
      </geometry>
    </collision>

    <visual>
      <origin rpy="0 0 0" xyz="0.15 0.05 -0.0465" />
      <geometry>
        <sphere radius="0.005" />
      </geometry>
    </visual>
    <collision>
      <origin rpy="0 0 0" xyz="0.15 0.05 -0.0465" />
      <geometry>
        <sphere radius="0.005" />
      </geometry>
    </collision>
    <visual>
      <origin rpy="0 0 0" xyz="0.15 -0.05 -0.0465" />
      <geometry>
        <sphere radius="0.005" />
      </geometry>
    </visual>
    <collision>
      <origin rpy="0 0 0" xyz="0.15 -0.05 -0.0465" />
      <geometry>
        <sphere radius="0.005" />
      </geometry>
    </collision>
  </link>
  <joint 
    name="leg_r6_joint"
    type="revolute">
    <origin 
      xyz="0 0 0"
      rpy="0 0 0" />
    <parent 
      link="leg_r5_link" />
    <child 
      link="leg_r6_link" />
    <axis 
      xyz="1 0 0" />
    <limit
      lower="-0.52"
      upper="0.61"
      effort="36"
      velocity="14" />
  </joint>

  <link name="rl_foot_toe">
    <collision>
      <origin 
        rpy="0 0 0"
        xyz="0 0 0"/>
      <geometry>
        <sphere radius="0.005"/>
      </geometry>
    </collision>
  </link>
  <joint 
    name="rl_foot_toe_joint"
    type="fixed">
    <origin 
      xyz="0.15 0.05 -0.0465"
      rpy="0 0 0" />
    <parent 
      link="leg_r6_link" />
    <child 
      link="rl_foot_toe" />
  </joint>
  <link 
    name="rl_foot_heel">
    <collision>
      <origin 
        rpy="0 0 0"
        xyz="0 0 0"/>
      <geometry>
        <sphere radius="0.005"/>
      </geometry>
    </collision>
  </link>
  <joint 
    name="rl_foot_heel_joint"
    type="fixed">
    <origin 
      xyz="-0.09 0.05 -0.0465"
      rpy="0 0 0" />
    <parent 
      link="leg_r6_link" />
    <child 
      link="rl_foot_heel" />
  </joint>

  <link 
    name="rr_foot_toe">
    <collision>
      <origin 
        rpy="0 0 0"
        xyz="0 0 0"/>
      <geometry>
        <sphere radius="0.005"/>
      </geometry>
    </collision>
  </link>
  <joint 
    name="rr_foot_toe_joint"
    type="fixed">
    <origin 
      xyz="0.15 -0.05 -0.0465"
      rpy="0 0 0" />
    <parent 
      link="leg_r6_link" />
    <child 
      link="rr_foot_toe" />
  </joint>
  <link 
    name="rr_foot_heel">
    <collision>
      <origin 
        rpy="0 0 0"
        xyz="0 0 0"/>
      <geometry>
        <sphere radius="0.005"/>
      </geometry>
    </collision>
  </link>
  <joint 
    name="rr_foot_heel_joint"
    type="fixed">
    <origin 
      xyz="-0.09 -0.05 -0.0465"
      rpy="0 0 0" />
    <parent 
      link="leg_r6_link" />
    <child 
      link="rr_foot_heel" />
  </joint>
  <link 
    name="r_foot_toe">
    <collision>
      <origin 
        rpy="0 0 0"
        xyz="0 0 0"/>
      <geometry>
        <sphere radius="0.005"/>
      </geometry>
    </collision>
  </link>
  <joint 
    name="r_foot_toe_joint"
    type="fixed">
    <origin 
      xyz="0.15 -0.0 -0.0465"
      rpy="0 0 0" />
    <parent 
      link="leg_r6_link" />
    <child 
      link="r_foot_toe" />
  </joint>
  <link 
    name="r_foot_heel">
    <collision>
      <origin 
        rpy="0 0 0"
        xyz="0 0 0"/>
      <geometry>
        <sphere radius="0.005"/>
      </geometry>
    </collision>
  </link>
  <joint 
    name="r_foot_heel_joint"
    type="fixed">
    <origin 
      xyz="-0.09 -0.0 -0.0465"
      rpy="0 0 0" />
    <parent 
      link="leg_r6_link" />
    <child 
      link="r_foot_heel" />
  </joint>

  <link
    name="zarm_l1_link">
    <inertial>
      <origin
        xyz="0.0146835191418715 -0.0166604103758634 -6.82857133371129E-05"
        rpy="0 0 0" />
      <mass
        value="0.794" />
      <inertia
        ixx="0.0002674432873971"
        ixy="-2.5654089149164E-05"
        ixz="-1.72966133127553E-07"
        iyy="0.000125796784291983"
        iyz="-1.66717296343013E-06"
        izz="0.000196186976742156" />
    </inertial>
    <visual>
      <origin
        xyz="0 0 0"
        rpy="0 0 0" />
      <geometry>
        <mesh
          filename="package://kuavo_assets/models/biped_s40/meshes/l_arm_pitch.obj" />
      </geometry>
      <material
        name="">
        <color
          rgba="1 1 1 1" />
      </material>
    </visual>    
  </link>
  <joint
    name="zarm_l1_joint"
    type="revolute">
    <origin
      xyz="-0.0175475823124921 0.254700000000031 0.324500000000024"
      rpy="0 0 0" />
    <parent
      link="base_link" />
    <child
      link="zarm_l1_link" />
    <axis
      xyz="0 1 0" />
    <limit 
      lower="-2.0933" 
      upper="0.5233" 
      effort="60" 
      velocity="14" />
    <dynamic
      damping="0.2" />
  </joint>

  <link
    name="zarm_l2_link">
    <inertial>
      <origin
        xyz="0.0222872651779299 0.0156945544195473 -0.0202262244341484"
        rpy="0 0 0" />
      <mass
        value="0.20735" />
      <inertia
        ixx="0.000160370067223081"
        ixy="6.30811840859269E-06"
        ixz="-1.13259246453495E-05"
        iyy="0.000262365778589962"
        iyz="3.14941259087024E-05"
        izz="0.00023601403628197" />
    </inertial>
    <visual>
      <origin
        xyz="0 0 0"
        rpy="0 0 0" />
      <geometry>
        <mesh
          filename="package://kuavo_assets/models/biped_s40/meshes/l_arm_roll.obj" />
      </geometry>
      <material
        name="">
        <color
          rgba="1 1 1 1" />
      </material>
    </visual>   
  </link>
  <joint
    name="zarm_l2_joint"
    type="revolute">
    <origin
      xyz="0 0 0"
      rpy="0 0 0" />
    <parent
      link="zarm_l1_link" />
    <child
      link="zarm_l2_link" />
    <axis
      xyz="1 0 0" />
    <limit 
      lower="-0.3489" 
      upper="2.0933" 
      effort="82.8" 
      velocity="14" />
    <dynamic
      damping="0.2" />
  </joint>

  <link
    name="zarm_l3_link">
    <inertial>
      <origin
        xyz="6.16940440451783E-05 0.00525815062784063 -0.128821944854616"
        rpy="0 0 0" />
      <mass
        value="1.120632" />
      <inertia
        ixx="7.00575957554699E-05"
        ixy="-6.81658291272877E-10"
        ixz="2.69427050743199E-10"
        iyy="8.53612265336777E-05"
        iyz="6.95899873075699E-06"
        izz="8.82223899453285E-05" />
    </inertial>
    <visual>
      <origin
        xyz="0 0 0"
        rpy="0 0 0" />
      <geometry>
        <mesh
          filename="package://kuavo_assets/models/biped_s40/meshes/l_arm_yaw.obj" />
      </geometry>
      <material
        name="">
        <color
          rgba="1 1 1 1" />
      </material>
    </visual>    
  </link>
  <joint
    name="zarm_l3_joint"
    type="revolute">
    <origin
      xyz="0 0 0"
      rpy="0 0 0" />
    <parent
      link="zarm_l2_link" />
    <child
      link="zarm_l3_link" />
    <axis
      xyz="0 0 1" />
    <limit 
      lower="-1.57" 
      upper="1.57" 
      effort="60" 
      velocity="14" />
    <dynamic
      damping="0.2" />
  </joint>
  
  <link
    name="zarm_l4_link">
    <inertial>
      <origin
        xyz="-1.4281929799409E-05 0.00938313949959718 -0.0522687552263489"
        rpy="0 0 0" />
      <mass
        value="0.395825" />
      <inertia
        ixx="9.558084476069E-05"
        ixy="-4.53863490387433E-08"
        ixz="5.39342118513253E-08"
        iyy="0.000126326373178391"
        iyz="-9.58160032696958E-06"
        izz="0.000121032474884238" />
    </inertial>
    <visual>
      <origin
        xyz="0 0 0"
        rpy="0 0 0" />
      <geometry>
        <mesh
          filename="package://kuavo_assets/models/biped_s40/meshes/l_forearm_pitch.obj" />
      </geometry>
      <material
        name="">
        <color
          rgba="1 1 1 1" />
      </material>
    </visual>    
  </link>
  <joint
    name="zarm_l4_joint"
    type="revolute">
    <origin
      xyz="0 0 -0.163599999999998"
      rpy="0 0 0" />
    <parent
      link="zarm_l3_link" />
    <child
      link="zarm_l4_link" />
    <axis
      xyz="0 1 0" />
    <limit lower="-2.0933" upper="0" effort="60" velocity="14" />
    <dynamic
      damping="0.2" />
  </joint>
  
  <link
    name="zarm_l5_link">
    <inertial>
      <origin
        xyz="0.000113133463122583 0.00969227839919062 0.0817960696431681"
        rpy="0 0 0" />
      <mass
        value="0.380792" />
      <inertia
        ixx="7.64923984145487E-05"
        ixy="8.51098127601464E-09"
        ixz="-1.4070355859132E-08"
        iyy="0.000122231132554914"
        iyz="1.11226968994633E-06"
        izz="8.44935061342021E-05" />
    </inertial>
    <visual>
      <origin
        xyz="0 0 0"
        rpy="0 0 0" />
      <geometry>
        <mesh
          filename="package://kuavo_assets/models/biped_s40/meshes/l_hand_yaw.obj" />
      </geometry>
      <material
        name="">
        <color
          rgba="1 1 1 1" />
      </material>
    </visual>   
  </link>
  <joint
    name="zarm_l5_joint"
    type="revolute">
    <origin
      xyz="0 0 -0.191049997298861"
      rpy="0 0 0" />
    <parent
      link="zarm_l4_link" />
    <child
      link="zarm_l5_link" />
    <axis
      xyz="0 0 1" />
    <limit 
      lower="-1.657" 
      upper="1.657" 
      effort="6" 
      velocity="14" />
    <dynamic
      damping="0.2" />
  </joint>
  
  <link
    name="zarm_l6_link">
    <inertial>
      <origin
        xyz="0.00810609786663821 0.00489663150092601 0.00622488608908427"
        rpy="0 0 0" />
      <mass
        value="0.376651" />
      <inertia
        ixx="4.77321490368476E-05"
        ixy="3.05261917457107E-06"
        ixz="4.77827164947654E-06"
        iyy="3.43814769749139E-05"
        iyz="-4.59311499587155E-06"
        izz="2.49955336560135E-05" />
    </inertial>
    <visual>
      <origin
        xyz="0 0 0"
        rpy="0 0 0" />
      <geometry>
        <mesh
          filename="package://kuavo_assets/models/biped_s40/meshes/l_hand_pitch.obj" />
      </geometry>
      <material
        name="">
        <color
          rgba="1 1 1 1" />
      </material>
    </visual>    
  </link>
  <joint
    name="zarm_l6_joint"
    type="revolute">
    <origin
      xyz="0 0 0"
      rpy="0 0 0" />
    <parent
      link="zarm_l5_link" />
    <child
      link="zarm_l6_link" />
    <axis
      xyz="0 1 0" />
    <limit 
      lower="-1.657" 
      upper="1.657" 
      effort="6" 
      velocity="14" />
    <dynamic
      damping="0.2" />
  </joint>
  
  <link
    name="zarm_l7_link">
    <inertial>
      <origin
        xyz="0.0055750097939089 0.00647363667890594 -0.0826245715087526"
        rpy="0 0 0" />
      <mass
        value="0.704669" />
      <inertia
        ixx="8.04371746531483E-05"
        ixy="2.770174858381E-07"
        ixz="-4.63354764745673E-06"
        iyy="0.000116536814280971"
        iyz="1.04534418501281E-05"
        izz="0.000111690600253046" />
    </inertial>
    <visual>
      <origin
        xyz="0 0 0"
        rpy="0 0 0" />
      <geometry>
        <mesh
          filename="package://kuavo_assets/models/biped_s40/meshes/l_hand_roll.obj" />
      </geometry>
      <material
        name="">
        <color
          rgba="1 1 1 1" />
      </material>
    </visual>   
  </link>
  <joint
    name="zarm_l7_joint"
    type="revolute">
    <origin
      xyz="0 0 0"
      rpy="0 0 0" />
    <parent
      link="zarm_l6_link" />
    <child
      link="zarm_l7_link" />
    <axis
      xyz="1 0 0" />
    <limit 
      lower="-1.57" 
      upper="1.57" 
      effort="6" 
      velocity="14" />
    <dynamic
      damping="0.2" />
  </joint>
  
  <link
    name="zarm_l7_end_effector">
    <collision>
        <origin rpy="0 0 0" xyz="0 0 0"/>
        <geometry>
            <sphere radius="0.005"/>
        </geometry>
    </collision>
  </link>
  <joint
    name="zarm_l7_joint_end_effector"
    type="fixed">
    <origin
      xyz="0.00 -0.03 -0.17"
      rpy="0 0 0" />
    <parent
      link="zarm_l7_link" />
    <child
      link="zarm_l7_end_effector" />
  </joint>

  <link
    name="zarm_r1_link">
    <inertial>
      <origin
        xyz="0.0146743511434554 0.0168298008224051 -8.16711977456031E-05"
        rpy="0 0 0" />
      <mass
        value="0.794" />
      <inertia
        ixx="0.000267364314112701"
        ixy="2.58822573731612E-05"
        ixz="-1.74450019197634E-07"
        iyy="0.000125724274127356"
        iyz="1.71810516637517E-06"
        izz="0.000196179895851995" />
    </inertial>
    <visual>
      <origin
        xyz="0 0 0"
        rpy="0 0 0" />
      <geometry>
        <mesh
          filename="package://kuavo_assets/models/biped_s40/meshes/r_arm_pitch.obj" />
      </geometry>
      <material
        name="">
        <color
          rgba="1 1 1 1" />
      </material>
    </visual>   
  </link>
  <joint
    name="zarm_r1_joint"
    type="revolute">
    <origin
      xyz="-0.0175475823119764 -0.254700000000003 0.324500000000024"
      rpy="0 0 0" />
    <parent
      link="base_link" />
    <child
      link="zarm_r1_link" />
    <axis
      xyz="0 1 0" />
    <limit 
      lower="-2.0933" 
      upper="0.5233" 
      effort="60" 
      velocity="14" />
    <dynamic
      damping="0.2" />
  </joint>
  
  <link
    name="zarm_r2_link">
    <inertial>
      <origin
        xyz="0.0223009070030529 -0.0156950170482436 -0.0202307747650334"
        rpy="0 0 0" />
      <mass
        value="0.20735" />
      <inertia
        ixx="0.00016058853411588"
        ixy="-6.25733649402466E-06"
        ixz="-1.13236198708706E-05"
        iyy="0.000262566981542989"
        iyz="-3.14930415013909E-05"
        izz="0.000236151535262186" />
    </inertial>
    <visual>
      <origin
        xyz="0 0 0"
        rpy="0 0 0" />
      <geometry>
        <mesh
          filename="package://kuavo_assets/models/biped_s40/meshes/r_arm_roll.obj" />
      </geometry>
      <material
        name="">
        <color
          rgba="1 1 1 1" />
      </material>
    </visual>   
  </link>
  <joint
    name="zarm_r2_joint"
    type="revolute">
    <origin
      xyz="0 0 0"
      rpy="0 0 0" />
    <parent
      link="zarm_r1_link" />
    <child
      link="zarm_r2_link" />
    <axis
      xyz="1 0 0" />
    <limit 
      lower="-2.0933" 
      upper="0.3489" 
      effort="82.8" 
      velocity="14" />
    <dynamic
      damping="0.2" />
  </joint>
  
  <link
    name="zarm_r3_link">
    <inertial>
      <origin
        xyz="-4.82749435400213E-05 -0.0052581506278393 -0.128821944854617"
        rpy="0 0 0" />
      <mass
        value="1.120632" />
      <inertia
        ixx="7.00575957554697E-05"
        ixy="-6.81658260938682E-10"
        ixz="-2.69427064597612E-10"
        iyy="8.53612265336775E-05"
        iyz="-6.95899873075696E-06"
        izz="8.82223899453284E-05" />
    </inertial>
    <visual>
      <origin
        xyz="0 0 0"
        rpy="0 0 0" />
      <geometry>
        <mesh
          filename="package://kuavo_assets/models/biped_s40/meshes/r_arm_yaw.obj" />
      </geometry>
      <material
        name="">
        <color
          rgba="1 1 1 1" />
      </material>
    </visual>    
  </link>
  <joint
    name="zarm_r3_joint"
    type="revolute">
    <origin
      xyz="0 0 0"
      rpy="0 0 0" />
    <parent
      link="zarm_r2_link" />
    <child
      link="zarm_r3_link" />
    <axis
      xyz="0 0 1" />
    <limit 
      lower="-1.57" 
      upper="1.57" 
      effort="60" 
      velocity="14" />
    <dynamic
      damping="0.2" />
  </joint>
  
  <link
    name="zarm_r4_link">
    <inertial>
      <origin
        xyz="-0.000127232990745116 -0.00951602649232586 -0.0522687552263488"
        rpy="0 0 0" />
      <mass
        value="0.395825" />
      <inertia
        ixx="9.55808447606916E-05"
        ixy="-4.53863489774233E-08"
        ixz="-5.41060583443891E-08"
        iyy="0.000126326373178394"
        iyz="9.40982665987077E-06"
        izz="0.00012103247488424" />
    </inertial>
    <visual>
      <origin
        xyz="0 0 0"
        rpy="0 0 0" />
      <geometry>
        <mesh
          filename="package://kuavo_assets/models/biped_s40/meshes/r_forearm_pitch.obj" />
      </geometry>
      <material
        name="">
        <color
          rgba="1 1 1 1" />
      </material>
    </visual>   
  </link>
  <joint
    name="zarm_r4_joint"
    type="revolute">
    <origin
      xyz="0 0 -0.1636"
      rpy="0 0 0" />
    <parent
      link="zarm_r3_link" />
    <child
      link="zarm_r4_link" />
    <axis
      xyz="0 1 0" />
    <limit 
      lower="-2.0933" 
      upper="0" 
      effort="60" 
      velocity="14" />
    <dynamic
      damping="0.2" />
  </joint>
  
  <link
    name="zarm_r5_link">
    <inertial>
      <origin
        xyz="-0.000113133331993445 -0.0097448351680483 0.0817960724173413"
        rpy="0 0 0" />
      <mass
        value="0.380792" />
      <inertia
        ixx="7.64923982725728E-05"
        ixy="8.51115986496426E-09"
        ixz="1.40703608309957E-08"
        iyy="0.000122231132626729"
        iyz="-1.11226978982942E-06"
        izz="8.44935061081861E-05" />
    </inertial>
    <visual>
      <origin
        xyz="0 0 0"
        rpy="0 0 0" />
      <geometry>
        <mesh
          filename="package://kuavo_assets/models/biped_s40/meshes/r_hand_yaw.obj" />
      </geometry>
      <material
        name="">
        <color
          rgba="1 1 1 1" />
      </material>
    </visual>
  </link>
  <joint
    name="zarm_r5_joint"
    type="revolute">
    <origin
      xyz="0 0 -0.191050000125729"
      rpy="0 0 0" />
    <parent
      link="zarm_r4_link" />
    <child
      link="zarm_r5_link" />
    <axis
      xyz="0 0 1" />
    <limit 
      lower="-1.657" 
      upper="1.657" 
      effort="6" 
      velocity="14" />
    <dynamic
      damping="0.2" />
  </joint>
  
  <link
    name="zarm_r6_link">
    <inertial>
      <origin
        xyz="0.00735986990228184 -0.0047523802551166 0.00605888061339196"
        rpy="0 0 0" />
      <mass
        value="0.376651" />
      <inertia
        ixx="4.77321358097824E-05"
        ixy="-2.99709432812988E-06"
        ixz="4.71488437974188E-06"
        iyy="3.42470226388499E-05"
        iyz="4.61094199971347E-06"
        izz="2.51299600072388E-05" />
    </inertial>
    <visual>
      <origin
        xyz="0 0 0"
        rpy="0 0 0" />
      <geometry>
        <mesh
          filename="package://kuavo_assets/models/biped_s40/meshes/r_hand_pitch.obj" />
      </geometry>
      <material
        name="">
        <color
          rgba="1 1 1 1" />
      </material>
    </visual>
  </link>
  <joint
    name="zarm_r6_joint"
    type="revolute">
    <origin
      xyz="0 0 0"
      rpy="0 0 0" />
    <parent
      link="zarm_r5_link" />
    <child
      link="zarm_r6_link" />
    <axis
      xyz="0 1 0" />
    <limit 
      lower="-1.657" 
      upper="1.657" 
      effort="6" 
      velocity="14" />
    <dynamic
      damping="0.2" />
  </joint>
  
  <link
    name="zarm_r7_link">
    <inertial>
      <origin
        xyz="0.0045944493552252 -0.00586927010446042 -0.0836324643988434"
        rpy="0 0 0" />
      <mass
        value="0.704669" />
      <inertia
        ixx="0.000160651543151659"
        ixy="-5.37963063503334E-07"
        ixz="-9.47669219939636E-06"
        iyy="0.000229393712149694"
        iyz="-2.08351527945055E-05"
        izz="0.000219277776699058" />
    </inertial>
    <visual>
      <origin
        xyz="0 0 0"
        rpy="0 0 0" />
      <geometry>
        <mesh
          filename="package://kuavo_assets/models/biped_s40/meshes/r_hand_roll.obj" />
      </geometry>
      <material
        name="">
        <color
          rgba="1 1 1 1" />
      </material>
    </visual>
  </link>
  <joint
    name="zarm_r7_joint"
    type="revolute">
    <origin
      xyz="0 0 0"
      rpy="0 0 0" />
    <parent
      link="zarm_r6_link" />
    <child
      link="zarm_r7_link" />
    <axis
      xyz="1 0 0" />
    <limit 
      lower="-1.57" 
      upper="1.57" 
      effort="6" 
      velocity="14" />
    <dynamic
      damping="0.2" />
  </joint>

  <link
    name="zarm_r7_end_effector">
    <collision>
        <origin rpy="0 0 0" xyz="0 0 0"/>
        <geometry>
            <sphere radius="0.005"/>
        </geometry>
    </collision>
  </link>
  <joint
    name="zarm_r7_joint_end_effector"
    type="fixed">
    <origin
      xyz="0.00 0.03 -0.17"
      rpy="0 0 0" />
    <parent
      link="zarm_r7_link" />
    <child
      link="zarm_r7_end_effector" />
  </joint>
 <link
    name="neck_motor">
    <inertial>
      <origin
        xyz="-3.77475828372553E-15 0.0124496461817263 -0.0298176941106402"
        rpy="0 0 0" />
      <mass
        value="0.0290833361791932" />
      <inertia
        ixx="2.31088609398575E-05"
        ixy="-8.31934611144254E-20"
        ixz="9.83952420743037E-21"
        iyy="2.23207774381225E-05"
        iyz="-5.88352640523343E-06"
        izz="2.78125851778324E-05" />
    </inertial>
    <visual>
      <origin
        xyz="0 0 0"
        rpy="0 0 0" />
      <geometry>
        <mesh
          filename="package://kuavo_assets/models/biped_s40/meshes/neck_motor.STL" />
      </geometry>
      <material
        name="">
        <color
          rgba="0.67843137254902 0.654901960784314 0.827450980392157 1" />
      </material>
    </visual>
    <collision>
      <origin
        xyz="0 0 0"
        rpy="0 0 0" />
      <geometry>
        <mesh
          filename="package://kuavo_assets/models/biped_s40/meshes/neck_motor.STL" />
      </geometry>
    </collision>
  </link>
  <joint
    name="neck_joint_yaw"
    type="revolute">
    <origin
      xyz="-0.0175 0 0.5014"
      rpy="0 0 0" />
    <parent
      link="base_link" />
    <child
      link="neck_motor" />
    <axis
      xyz="0 0 1" />
    <limit
      lower="-1.57"
      upper="1.57"
      effort="0"
      velocity="0" />
  </joint>
  <link
    name="head">
    <inertial>
      <origin
        xyz="0.0110644219279026 0.000692305509442714 0.0585997503013596"
        rpy="0 0 0" />
      <mass
        value="0.658604769949708" />
      <inertia
        ixx="0.00170712579893411"
        ixy="6.4192791555892E-08"
        ixz="0.000505818824164995"
        iyy="0.00174953220790319"
        iyz="5.43403107472801E-06"
        izz="0.00222561108308001" />
    </inertial>
    <visual>
      <origin
        xyz="0 0 0"
        rpy="0 0 0" />
      <geometry>
        <mesh
          filename="package://kuavo_assets/models/biped_s40/meshes/head.STL" />
      </geometry>
      <material
        name="">
        <color
          rgba="1 1 1 1" />
      </material>
    </visual>
    <collision>
      <origin
        xyz="0 0 0"
        rpy="0 0 0" />
      <geometry>
        <mesh
          filename="package://kuavo_assets/models/biped_s40/meshes/head.STL" />
      </geometry>
    </collision>
  </link>
  <joint
    name="neck_joint_pitch"
    type="revolute">
    <origin
      xyz="0 0 0"
      rpy="0 0 0" />
    <parent
      link="neck_motor" />
    <child
      link="head" />
    <axis
      xyz="0 1 0" />
    <limit
      lower="-0.52"
      upper="0.52"
      effort="0"
      velocity="0" />
  </joint>
  <link
    name="camera">
    <inertial>
      <origin
        xyz="-0.00630026108299864 -0.0160960633638387 -4.88215001732684E-05"
        rpy="0 0 0" />
      <mass
        value="0.0170255961584929" />
      <inertia
        ixx="1.09182620877589E-05"
        ixy="-1.05354237503678E-07"
        ixz="-1.05871360812816E-08"
        iyy="8.57178923448406E-07"
        iyz="-1.64018481023057E-08"
        izz="1.02869873531782E-05" />
    </inertial>
    <visual>
      <origin
        xyz="0 0 0"
        rpy="0 0 0" />
      <geometry>
        <mesh
          filename="package://kuavo_assets/models/biped_s40/meshes/camera.STL" />
      </geometry>
      <material
        name="">
        <color
          rgba="1 1 1 1" />
      </material>
    </visual>
    <collision>
      <origin
        xyz="0 0 0"
        rpy="0 0 0" />
      <geometry>
        <mesh
          filename="package://kuavo_assets/models/biped_s40/meshes/camera.STL" />
      </geometry>
    </collision>
  </link>
  <joint
    name="camera"
    type="fixed">
    <origin
      xyz="0.0919101155958193 0.0175000000022731 0.0617838754768194"
      rpy="0 0.610865238198013 0" />
    <parent
      link="head" />
    <child
      link="camera" />
    <axis
      xyz="0 0 0" />
  </joint>
</robot>
