<mujoco model="biped_s4">
  <compiler angle="radian" meshdir="../meshes/"/>
  <size njmax="500" nconmax="100" />
  <asset>
    <texture type="skybox" builtin="gradient" rgb1="0.4 0.6 0.8" width="128" height="128"/>
    <texture name="grid" type="2d" builtin="checker" rgb1=".1 .2 .3" rgb2=".2 .3 .4" width="300" height="300"/>
    <material name="grid" texture="grid" texrepeat="8 8" reflectance=".1"/>
    <mesh name="torso" file="torso.obj"/>
    <mesh name="l_leg_roll" file="l_leg_roll.obj"/>
    <mesh name="l_leg_yaw" file="l_leg_yaw.obj"/>
    <mesh name="l_leg_pitch" file="l_leg_pitch.obj"/>
    <mesh name="l_knee" file="l_knee.obj"/>
    <mesh name="l_foot_pitch" file="l_foot_pitch.obj"/>
    <mesh name="l_foot_roll" file="l_foot_roll.obj"/>
    <mesh name="r_leg_roll" file="r_leg_roll.obj"/>
    <mesh name="r_leg_yaw" file="r_leg_yaw.obj"/>
    <mesh name="r_leg_pitch" file="r_leg_pitch.obj"/>
    <mesh name="r_knee" file="r_knee.obj"/>
    <mesh name="r_foot_pitch" file="r_foot_pitch.obj"/>
    <mesh name="r_foot_roll" file="r_foot_roll.obj"/>
    <mesh name="l_arm_pitch" file="l_arm_pitch.STL" />
    <mesh name="l_arm_roll" file="l_arm_roll.STL" />
    <mesh name="l_arm_yaw" file="l_arm_yaw.STL" />
    <mesh name="l_foream" file="l_foream.STL" />
    <mesh name="l_hand_yaw" file="l_hand_yaw.STL" />
    <mesh name="l_hand_roll" file="l_hand_roll.STL" />
    <mesh name="l_hand_pitch" file="l_hand_pitch.obj" />
    <mesh name="r_arm_pitch" file="r_arm_pitch.STL" />
    <mesh name="r_arm_roll" file="r_arm_roll.STL" />
    <mesh name="r_arm_yaw" file="r_arm_yaw.STL" />
    <mesh name="r_foream" file="r_foream.STL" />
    <mesh name="r_hand_yaw" file="r_hand_yaw.STL" />
    <mesh name="r_hand_roll" file="r_hand_roll.STL" />
    <mesh name="r_hand_pitch" file="r_hand_pitch.obj" />
    <mesh name="neck_motor" file="neck_motor.STL" />
    <mesh name="head" file="head.STL" />
    <mesh name="camera" file="camera.STL" />
  </asset>
  <worldbody>
    <body name="base_link" pos="0 0 0.78">
      <freejoint/>
      <inertial pos="0.0 0.0 0.12722577" quat="1.00000  0.00000  0.00002 -0.00003" mass="23.97153" diaginertia="0.62588371 0.56247677 0.20014604" />
      <geom type="mesh" contype="0" conaffinity="0" group="1" rgba="0.43137 0.45098 0.43137 1" mesh="torso"/>
      <geom type="mesh" rgba="0.75294 0.75294 0.75294 1" mesh="torso" />
      <site name="imu" pos="0 0 0"/>
      <body name="leg_l1_link" pos="-0.139 0.088087 -0.065549">
        <inertial pos="0.0661423 -1.19e-06 -0.00862806" quat="-0.00036611 0.685786 0.000388541 0.727803" mass="1.53801" diaginertia="0.00367033 0.00282649 0.00188822"/>
        <joint name="leg_l1_joint" pos="0 0 0" axis="1 0 0" range="-0.31 0.66" actuatorfrcrange="-85 85" damping='0.2' />
        <geom type="mesh" contype="0" conaffinity="0" group="1" density="0" rgba="0.6902 0.65882 0.63922 1" mesh="l_leg_roll"/>
        <body name="leg_l2_link" pos="0.1365 -0.0010866 -0.033901">
          <inertial pos="0 0.046104 -0.132561" quat="0.406465 0.913665 0.00146124 -0.000707497" mass="1.60097" diaginertia="0.0069836 0.00577369 0.00365952"/>
          <joint name="leg_l2_joint" pos="0 0 0" axis="0 0 1" range="-0.52 1.04" actuatorfrcrange="-60 60" damping='0.2' />
          <geom type="mesh" contype="0" conaffinity="0" group="1" density="0" rgba="0.65098 0.61961 0.58824 1" mesh="l_leg_yaw"/>
          <body name="leg_l3_link" pos="0 0.094 -0.09">
            <inertial pos="-0.00644903 -0.0981356 -0.0535761" quat="0.680972 -0.0265435 0.0402869 0.730718" mass="2.46657" diaginertia="0.0233349 0.022619 0.00397939"/>
            <joint name="leg_l3_joint" pos="0 0 0" axis="0 1 0" range="-1.83 1.04" actuatorfrcrange="-85 85" damping='0.2' />
            <geom type="mesh" contype="0" conaffinity="0" group="1" density="0" rgba="0.52941 0.54902 0.54902 1" mesh="l_leg_pitch"/>
            <body name="leg_l4_link" pos="0.004136 -0.06635 -0.24997">
              <inertial pos="0.00080045 -4.225e-05 -0.120497" quat="0.708481 -0.000629386 -0.0108666 0.705646" mass="1.62912" diaginertia="0.013595 0.0134393 0.000915523"/>
              <joint name="leg_l4_joint" pos="0 0 0" axis="0 1 0" range="0 2.18" actuatorfrcrange="-85 85" damping='0.2' />
              <geom type="mesh" contype="0" conaffinity="0" group="1" density="0" rgba="0.68627 0.65882 0.63922 1" mesh="l_knee"/>
              <body name="leg_l5_link" pos="0 -0.0022 -0.346">
                <inertial pos="0 -0.0209998 0" quat="0.5 0.5 -0.5 0.5" mass="0.0544445" diaginertia="7.28e-06 4.11e-06 4.11e-06"/>
                <joint name="leg_l5_joint" pos="0 0 0" axis="0 1 0" range="-0.61 0.52" actuatorfrcrange="-36 36" damping='0.2'/>
                <geom type="mesh" contype="0" conaffinity="0" group="1" density="0" rgba="0.6902 0.65882 0.63922 1" mesh="l_foot_pitch"/>
                <body name="leg_l6_link">
                  <inertial pos="-0.0355077 9.71466e-06 -0.0272597" quat="-0.000229205 0.628048 -0.000281424 0.778175" mass="0.470217" diaginertia="0.00146681 0.00133526 0.000364416"/>
                  <joint name="leg_l6_joint" pos="0 0 0" axis="1 0 0" range="-0.61 0.52" actuatorfrcrange="-36 36" damping='0.2' />
                  <geom type="mesh" contype="0" conaffinity="0" group="1" density="0" rgba="0.6902 0.65882 0.63922 1" mesh="l_foot_roll"/>
                  <geom size="0.005" pos="-0.09 0.05 -0.0465" contype="0" conaffinity="0" group="1" density="0" rgba="0.6902 0.65882 0.63922 1"/>
                  <geom size="0.005" pos="-0.09 0.05 -0.0465" rgba="0.6902 0.65882 0.63922 1"/>
                  <geom size="0.005" pos="-0.09 -0.05 -0.0465" contype="0" conaffinity="0" group="1" density="0" rgba="0.6902 0.65882 0.63922 1"/>
                  <geom size="0.005" pos="-0.09 -0.05 -0.0465" rgba="0.6902 0.65882 0.63922 1"/>
                  <geom size="0.005" pos="0.15 0.05 -0.0465" contype="0" conaffinity="0" group="1" density="0" rgba="0.6902 0.65882 0.63922 1"/>
                  <geom size="0.005" pos="0.15 0.05 -0.0465" rgba="0.6902 0.65882 0.63922 1"/>
                  <geom size="0.005" pos="0.15 -0.05 -0.0465" contype="0" conaffinity="0" group="1" density="0" rgba="0.6902 0.65882 0.63922 1"/>
                  <geom size="0.005" pos="0.15 -0.05 -0.0465" rgba="0.6902 0.65882 0.63922 1"/>
                  <geom type="box" size="0.12 0.05 0.005" pos="0.03 0 -0.0465" contype="1" conaffinity="1" group="1" density="0" rgba="0.1 0.6 0.1 0.2"/>
                </body>
              </body>
            </body>
          </body>
        </body>
      </body>
      <body name="leg_r1_link" pos="-0.139 -0.088087 -0.065549">
        <inertial pos="0.0661423 1.19e-06 -0.00862806" quat="0.000366114 0.685786 -0.000388545 0.727803" mass="1.53801" diaginertia="0.00367033 0.00282648 0.00188822"/>
        <joint name="leg_r1_joint" pos="0 0 0" axis="1 0 0" range="-0.6629 0.314" actuatorfrcrange="-85 85" damping='0.2' />
        <geom type="mesh" contype="0" conaffinity="0" group="1" density="0" rgba="0.6902 0.65882 0.63922 1" mesh="r_leg_roll"/>
        <body name="leg_r2_link" pos="0.1365 0.0010866 -0.033901">
          <inertial pos="4.661e-05 -0.0461036 -0.132574" quat="0.928414 0.371529 0.00156279 -0.00347123" mass="1.60097" diaginertia="0.00520443 0.00457962 0.00331423"/>
          <joint name="leg_r2_joint" pos="0 0 0" axis="0 0 1" range="-1.04 0.52" actuatorfrcrange="-60 60" damping='0.2' />
          <geom type="mesh" contype="0" conaffinity="0" group="1" density="0" rgba="0.65098 0.619608 0.588235 1" mesh="r_leg_yaw"/>
          <body name="leg_r3_link" pos="0 -0.094 -0.09">
            <inertial pos="-0.00644903 0.0981356 -0.0535761" quat="0.782763 0.0509103 -0.043864 0.618681" mass="2.46657" diaginertia="0.0236078 0.0224895 0.00397676"/>
            <joint name="leg_r3_joint" pos="0 0 0" axis="0 1 0" range="-1.83 1.04" actuatorfrcrange="-85 85" damping='0.2' />
            <geom type="mesh" contype="0" conaffinity="0" group="1" density="0" rgba="0.529412 0.54902 0.54902 1" mesh="r_leg_pitch"/>
            <body name="leg_r4_link" pos="0.004136 0.06635 -0.24997">
              <inertial pos="0.00080045 4.225e-05 -0.120497" quat="0.705646 -0.0108666 -0.000629386 0.708481" mass="1.62912" diaginertia="0.013595 0.0134393 0.000915523"/>
              <joint name="leg_r4_joint" pos="0 0 0" axis="0 1 0" range="0 2.18" actuatorfrcrange="-85 85" damping='0.2' />
              <geom type="mesh" contype="0" conaffinity="0" group="1" density="0" rgba="0.686275 0.658824 0.639216 1" mesh="r_knee"/>
              <body name="leg_r5_link" pos="0 0.0022 -0.346">
                <inertial pos="0 0.0210002 0" quat="0.5 0.5 -0.5 0.5" mass="0.0544445" diaginertia="7.28e-06 4.11e-06 4.11e-06"/>
                <joint name="leg_r5_joint" pos="0 0 0" axis="0 1 0" range="-0.61 0.52" actuatorfrcrange="-36 36" damping='0.2' />
                <geom type="mesh" contype="0" conaffinity="0" group="1" density="0" rgba="0.690196 0.658824 0.639216 1" mesh="r_foot_pitch"/>
                <body name="leg_r6_link">
                  <inertial pos="-0.0355078 -9.65506e-06 -0.0272597" quat="0.00022933 0.628048 0.00028129 0.778175" mass="0.470216" diaginertia="0.0014668 0.00133526 0.000364406"/>
                  <joint name="leg_r6_joint" pos="0 0 0" axis="1 0 0" range="-0.52 0.61" actuatorfrcrange="-36 36" damping='0.2' />
                  <geom type="mesh" contype="0" conaffinity="0" group="1" density="0" rgba="0.690196 0.658824 0.639216 1" mesh="r_foot_roll"/>
                  <geom size="0.005" pos="-0.09 0.05 -0.0465" contype="0" conaffinity="0" group="1" density="0" rgba="0.690196 0.658824 0.639216 1"/>
                  <geom size="0.005" pos="-0.09 0.05 -0.0465" rgba="0.690196 0.658824 0.639216 1"/>
                  <geom size="0.005" pos="-0.09 -0.05 -0.0465" contype="0" conaffinity="0" group="1" density="0" rgba="0.690196 0.658824 0.639216 1"/>
                  <geom size="0.005" pos="-0.09 -0.05 -0.0465" rgba="0.690196 0.658824 0.639216 1"/>
                  <geom size="0.005" pos="0.15 0.05 -0.0465" contype="0" conaffinity="0" group="1" density="0" rgba="0.690196 0.658824 0.639216 1"/>
                  <geom size="0.005" pos="0.15 0.05 -0.0465" rgba="0.690196 0.658824 0.639216 1"/>
                  <geom size="0.005" pos="0.15 -0.05 -0.0465" contype="0" conaffinity="0" group="1" density="0" rgba="0.690196 0.658824 0.639216 1"/>
                  <geom size="0.005" pos="0.15 -0.05 -0.0465" rgba="0.690196 0.658824 0.639216 1"/>
                  <geom type="box" size="0.12 0.05 0.005" pos="0.03 0 -0.0465" contype="1" conaffinity="1" group="1" density="0" rgba="0.1 0.6 0.1 0.2"/>
                </body>
              </body>
            </body>
          </body>
        </body>
      </body>
      <body name="zarm_l1_link" pos="-0.0174999 0.2927 0.3245">
        <inertial pos="-0.00082795 -0.0221802 0.00035481" quat="0.515301 0.518788 -0.473442 0.491097" mass="0.962" diaginertia="0.00227124 0.00224701 0.000985978" />
        <joint name="zarm_l1_joint" pos="0 0 0" axis="0 1 0" range="-2.0933 1.5233" actuatorfrcrange="-60.5 60.5" damping="0.2" />
        <geom type="mesh" contype="0" conaffinity="0" group="1" density="0" rgba="1 1 1 1" mesh="l_arm_pitch" />
        <body name="zarm_l2_link">
          <inertial pos="-0.00791105 -3.87e-06 -0.0465523" quat="0.705735 0.0444351 0.0445059 0.705679" mass="0.57" diaginertia="0.00211343 0.00163611 0.00121287" />
          <joint name="zarm_l2_joint" pos="0 0 0" axis="1 0 0" range="-1.3489 2.0933" actuatorfrcrange="-60.5 60.5" damping="0.2" />
          <geom type="mesh" contype="0" conaffinity="0" group="1" density="0" rgba="1 1 1 1" mesh="l_arm_roll" />
          <body name="zarm_l3_link">
            <inertial pos="0.00628241 0.00106989 -0.208777" quat="0.911037 0.018303 0.0661658 0.40657" mass="1.65" diaginertia="0.00832836 0.00821559 0.00194395" />
            <joint name="zarm_l3_joint" pos="0 0 0" axis="0 0 1" range="-1.57 1.57" actuatorfrcrange="-60.5 60.5" damping="0.2" />
            <geom type="mesh" contype="0" conaffinity="0" group="1" density="0" rgba="1 1 1 1" mesh="l_arm_yaw" />
            <body name="zarm_l4_link" pos="0.02 0 -0.2837">
              <inertial pos="-0.0161069 0.00142664 -0.0485658" quat="0.996021 0.00478025 -0.0885668 0.00867979" mass="0.429" diaginertia="0.0013642 0.00114091 0.000810952" />
              <joint name="zarm_l4_joint" pos="0 0 0" axis="0 1 0" range="-2.44 0" damping="0.2" />
              <geom type="mesh" contype="0" conaffinity="0" group="1" density="0" rgba="1 1 1 1" mesh="l_foream" />
              <body name="zarm_l5_link" pos="-0.02 0 -0.127037">
                <inertial pos="-0.00207477 0.00017906 -0.0507928" quat="0.705435 -0.0594871 -0.0597589 0.703741" mass="0.61" diaginertia="0.00145981 0.00107427 0.00082531" />
                <joint name="zarm_l5_joint" pos="0 0 0" axis="0 0 1" range="-1.657 1.657" actuatorfrcrange="-60.5 60.5" damping="0.2" />
                <geom type="mesh" contype="0" conaffinity="0" group="1" density="0" rgba="1 1 1 1" mesh="l_hand_yaw" />
                <body name="zarm_l6_link" pos="0.0002 0 -0.106463">
                  <inertial pos="-0.00111113 0.00325842 -0.0133761" quat="-0.025595 0.678572 -0.0408892 0.732948" mass="0.331" diaginertia="0.000282403 0.000268096 0.00022047" />
                  <joint name="zarm_l6_joint" pos="0 0 0" axis="1 0 0" range="-1.57 1.57" actuatorfrcrange="-60.5 60.5" damping="0.2" />
                  <geom type="mesh" contype="0" conaffinity="0" group="1" density="0" rgba="1 1 1 1" mesh="l_hand_roll" />
                  <body name="zarm_l7_link" pos="0 0 -0.021">
                    <inertial pos="0.00186197 0.0093677 -0.0905737" quat="0.944885 0.0271209 0.0295414 -0.324937" mass="0.640524" diaginertia="0.000724288 0.000690292 0.000121935" />
                    <joint name="zarm_l7_joint" pos="0 0 0" axis="0 1 0" range="-1.657 1.657" actuatorfrcrange="-60.5 60.5" damping="0.2" />
                    <geom type="mesh" contype="0" conaffinity="0" group="1" density="0" rgba="1 1 1 1" mesh="l_hand_pitch" />
                    <geom size="0.005" pos="0 -0.03 -0.17" />
                  </body>
                </body>
              </body>
            </body>
          </body>
        </body>
      </body>
      <body name="zarm_r1_link" pos="-0.0174999 -0.2927 0.3245">
        <inertial pos="-0.00437587 0.023125 0.00025053" quat="0.487828 0.51416 -0.488966 0.508502" mass="0.962" diaginertia="0.00128015 0.00121404 0.000546833" />
        <joint name="zarm_r1_joint" pos="0 0 0" axis="0 1 0" range="-2.0933 1.5233" actuatorfrcrange="-60.5 60.5" damping="0.2" />
        <geom type="mesh" contype="0" conaffinity="0" group="1" density="0" rgba="1 1 1 1" mesh="r_arm_pitch" />
        <body name="zarm_r2_link">
          <inertial pos="-0.00790107 -3.72e-06 -0.046699" quat="0.705808 0.0435559 0.0436204 0.705716" mass="0.57" diaginertia="0.00077187 0.00059709 0.00044322" />
          <joint name="zarm_r2_joint" pos="0 0 0" axis="1 0 0" range="-1.3489 2.0933" actuatorfrcrange="-60.5 60.5" damping="0.2" />
          <geom type="mesh" contype="0" conaffinity="0" group="1" density="0" rgba="1 1 1 1" mesh="r_arm_roll" />
          <body name="zarm_r3_link">
            <inertial pos="0.00633246 -0.00090927 -0.20893" quat="0.453393 0.063391 0.0220232 0.888781" mass="1.65" diaginertia="0.0025833 0.00254954 0.000613379" />
            <joint name="zarm_r3_joint" pos="0 0 0" axis="0 0 1" range="-1.57 1.57" actuatorfrcrange="-60.5 60.5" damping="0.2" />
            <geom type="mesh" contype="0" conaffinity="0" group="1" density="0" rgba="1 1 1 1" mesh="r_arm_yaw" />
            <body name="zarm_r4_link" pos="0.02 0 -0.2837">
              <inertial pos="-0.0169239 -0.00104775 -0.0520621" quat="0.995487 -0.0122982 -0.0929375 -0.0147222" mass="0.429" diaginertia="0.000757968 0.000642382 0.00043183" />
              <joint name="zarm_r4_joint" pos="0 0 0" axis="0 1 0" range="-2.44 0" damping="0.2" />
              <geom type="mesh" contype="0" conaffinity="0" group="1" density="0" rgba="1 1 1 1" mesh="r_foream" />
              <body name="zarm_r5_link" pos="-0.02 0 -0.127037">
                <inertial pos="-0.00129248 0.00018486 -0.0506669" quat="0.700915 -0.0638512 -0.0643595 0.70746" mass="0.61" diaginertia="0.00042574 0.000312526 0.000244564" />
                <joint name="zarm_r5_joint" pos="0 0 0" axis="0 0 1" range="-1.657 1.657" actuatorfrcrange="-60.5 60.5" damping="0.2" />
                <geom type="mesh" contype="0" conaffinity="0" group="1" density="0" rgba="1 1 1 1" mesh="r_hand_yaw" />
                <body name="zarm_r6_link" pos="0 0 -0.106463">
                  <inertial pos="-0.0010068 -0.00161113 -0.0142986" quat="-0.0452607 0.680017 -0.0149254 0.731646" mass="0.331" diaginertia="7.75429e-05 7.09953e-05 6.18918e-05" />
                  <joint name="zarm_r6_joint" pos="0 0 0" axis="1 0 0" range="-1.57 1.57" actuatorfrcrange="-60.5 60.5" damping="0.2" />
                  <geom type="mesh" contype="0" conaffinity="0" group="1" density="0" rgba="1 1 1 1" mesh="r_hand_roll" />
                  <body name="zarm_r7_link" pos="0 0 -0.021">
                    <inertial pos="0.00137853 -0.0100092 -0.0921314" quat="0.940661 -0.0336644 0.0281912 0.336495" mass="0.640524" diaginertia="0.000707691 0.000674371 0.000116299" />
                    <joint name="zarm_r7_joint" pos="0 0 0" axis="0 1 0" range="-1.657 1.657" actuatorfrcrange="-60.5 60.5" damping="0.2" />
                    <geom type="mesh" contype="0" conaffinity="0" group="1" density="0" rgba="1 1 1 1" mesh="r_hand_pitch" />
                    <geom size="0.005" pos="0 0.03 -0.17" />
                  </body>
                </body>
              </body>
            </body>
          </body>
        </body>
      </body>
      <body name="neck_motor" pos="-0.0175 0 0.5014">
            <inertial pos="0 0.0124496 -0.0298177" quat="0.340162 0.619911 -0.619911 0.340162" mass="0.0290833" diaginertia="3.15594e-05 2.31089e-05 1.85739e-05" />
            <joint name="neck_motor" pos="0 0 0" axis="0 0 1" limited="true" range="-1.57 1.57" />
            <geom type="mesh" contype="0" conaffinity="0" group="1" rgba="0.678431 0.654902 0.827451 1" mesh="neck_motor" />
            <geom type="mesh" rgba="0.678431 0.654902 0.827451 1" mesh="neck_motor" />
            <body name="head" pos="0 0 0">
                <inertial pos="0.0129709 0.000710238 0.05877" quat="-0.00224721 0.862414 0.00456122 0.506178" mass="0.67563" diaginertia="0.0026087 0.00184615 0.00144101" />
                <joint name="head" pos="0 0 0" axis="0 1 0" limited="true" range="-0.52 0.52" />
                <geom type="mesh" contype="0" conaffinity="0" group="1" rgba="1 1 1 1" mesh="head" />
                <geom type="mesh" rgba="1 1 1 1" mesh="head" />
                <geom pos="0.0919101 0.0175 0.0617839" quat="0.953717 0 0.300706 0" type="mesh" contype="0" conaffinity="0" group="1" rgba="1 1 1 1" mesh="camera" />
                <geom pos="0.0919101 0.0175 0.0617839" quat="0.953717 0 0.300706 0" type="mesh" rgba="1 1 1 1" mesh="camera" />
            </body>
        </body>
    </body>
  </worldbody>
  <actuator>
        <motor gear="1" joint="leg_l1_joint" name="leg_l1_motor" ctrllimited="true"  ctrlrange='-150 150'/>
        <motor gear="1" joint="leg_l2_joint" name="leg_l2_motor" ctrllimited="true"  ctrlrange='-150 150'/>
        <motor gear="1" joint="leg_l3_joint" name="leg_l3_motor" ctrllimited="true"  ctrlrange='-200 200'/>
        <motor gear="1" joint="leg_l4_joint" name="leg_l4_motor" ctrllimited="true"  ctrlrange='-200 200'/>
        <motor gear="1" joint="leg_l5_joint" name="leg_l5_motor" ctrllimited="true"  ctrlrange='-90 90'/>
        <motor gear="1" joint="leg_l6_joint" name="leg_l6_motor" ctrllimited="true"  ctrlrange='-90 90'/>

        <motor gear="1" joint="leg_r1_joint" name="leg_r1_motor" ctrllimited="true"  ctrlrange='-150 150'/>
        <motor gear="1" joint="leg_r2_joint" name="leg_r2_motor" ctrllimited="true"  ctrlrange='-150 150'/>
        <motor gear="1" joint="leg_r3_joint" name="leg_r3_motor" ctrllimited="true"  ctrlrange='-200 200'/>
        <motor gear="1" joint="leg_r4_joint" name="leg_r4_motor" ctrllimited="true"  ctrlrange='-200 200'/>
        <motor gear="1" joint="leg_r5_joint" name="leg_r5_motor" ctrllimited="true"  ctrlrange='-90 90'/>
        <motor gear="1" joint="leg_r6_joint" name="leg_r6_motor" ctrllimited="true"  ctrlrange='-90 90'/>

        <motor gear="1" joint="zarm_l1_joint" name="zarm_l1_motor" ctrllimited="true"  ctrlrange='-150 150'/>
        <motor gear="1" joint="zarm_l2_joint" name="zarm_l2_motor" ctrllimited="true"  ctrlrange='-150 150'/>
        <motor gear="1" joint="zarm_l3_joint" name="zarm_l3_motor" ctrllimited="true"  ctrlrange='-200 200'/>
        <motor gear="1" joint="zarm_l4_joint" name="zarm_l4_motor" ctrllimited="true"  ctrlrange='-200 200'/>
        <motor gear="1" joint="zarm_l5_joint" name="zarm_l5_motor" ctrllimited="true"  ctrlrange='-90 90'/>
        <motor gear="1" joint="zarm_l6_joint" name="zarm_l6_motor" ctrllimited="true"  ctrlrange='-90 90'/>
        <motor gear="1" joint="zarm_l7_joint" name="zarm_l7_motor" ctrllimited="true"  ctrlrange='-90 90'/>

        <motor gear="1" joint="zarm_r1_joint" name="zarm_r1_motor" ctrllimited="true"  ctrlrange='-150 150'/>
        <motor gear="1" joint="zarm_r2_joint" name="zarm_r2_motor" ctrllimited="true"  ctrlrange='-150 150'/>
        <motor gear="1" joint="zarm_r3_joint" name="zarm_r3_motor" ctrllimited="true"  ctrlrange='-200 200'/>
        <motor gear="1" joint="zarm_r4_joint" name="zarm_r4_motor" ctrllimited="true"  ctrlrange='-200 200'/>
        <motor gear="1" joint="zarm_r5_joint" name="zarm_r5_motor" ctrllimited="true"  ctrlrange='-90 90'/>
        <motor gear="1" joint="zarm_r6_joint" name="zarm_r6_motor" ctrllimited="true"  ctrlrange='-90 90'/>
        <motor gear="1" joint="zarm_r7_joint" name="zarm_r7_motor" ctrllimited="true"  ctrlrange='-90 90'/>
        <motor gear="1" joint="neck_motor" name="head_yaw_motor" ctrllimited="true"  ctrlrange='-90 90'/>
        <motor gear="1" joint="head" name="head_pitch_motor" ctrllimited="true"  ctrlrange='-90 90'/>
  </actuator>
  <sensor>
      <accelerometer name="BodyAcc" site="imu"/>
      <velocimeter name="BodyVel" site="imu"/>
      <gyro name="BodyGyro" site="imu"/>
      <framepos name="BodyPos" objtype="site" objname="imu"/>
      <framequat name="BodyQuat" objtype="site" objname="imu"/>

      <jointpos name="leg_l1_pos" joint="leg_l1_joint"/>
      <jointpos name="leg_l2_pos" joint="leg_l2_joint"/>
      <jointpos name="leg_l3_pos" joint="leg_l3_joint"/>
      <jointpos name="leg_l4_pos" joint="leg_l4_joint"/>
      <jointpos name="leg_l5_pos" joint="leg_l5_joint"/>
      <jointpos name="leg_l6_pos" joint="leg_l6_joint"/>

      <jointpos name="leg_r1_pos" joint="leg_r1_joint"/>
      <jointpos name="leg_r2_pos" joint="leg_r2_joint"/>
      <jointpos name="leg_r3_pos" joint="leg_r3_joint"/>
      <jointpos name="leg_r4_pos" joint="leg_r4_joint"/>
      <jointpos name="leg_r5_pos" joint="leg_r5_joint"/>
      <jointpos name="leg_r6_pos" joint="leg_r6_joint"/>

      <jointpos name="zarm_l1_pos" joint="zarm_l1_joint"/>
      <jointpos name="zarm_l2_pos" joint="zarm_l2_joint"/>
      <jointpos name="zarm_l3_pos" joint="zarm_l3_joint"/>
      <jointpos name="zarm_l4_pos" joint="zarm_l4_joint"/>
      <jointpos name="zarm_l5_pos" joint="zarm_l5_joint"/>
      <jointpos name="zarm_l6_pos" joint="zarm_l6_joint"/>
      <jointpos name="zarm_l7_pos" joint="zarm_l7_joint"/>

      <jointpos name="zarm_r1_pos" joint="zarm_r1_joint"/>
      <jointpos name="zarm_r2_pos" joint="zarm_r2_joint"/>
      <jointpos name="zarm_r3_pos" joint="zarm_r3_joint"/>
      <jointpos name="zarm_r4_pos" joint="zarm_r4_joint"/>
      <jointpos name="zarm_r5_pos" joint="zarm_r5_joint"/>
      <jointpos name="zarm_r6_pos" joint="zarm_r6_joint"/>
      <jointpos name="zarm_r7_pos" joint="zarm_r7_joint"/>
      <jointpos name="head_yaw_pos" joint="neck_motor"/>
      <jointpos name="head_pitch_pos" joint="head"/>

      <jointvel name="leg_l1_vel" joint="leg_l1_joint"/>
      <jointvel name="leg_l2_vel" joint="leg_l2_joint"/>
      <jointvel name="leg_l3_vel" joint="leg_l3_joint"/>
      <jointvel name="leg_l4_vel" joint="leg_l4_joint"/>
      <jointvel name="leg_l5_vel" joint="leg_l5_joint"/>
      <jointvel name="leg_l6_vel" joint="leg_l6_joint"/>

      <jointvel name="leg_r1_vel" joint="leg_r1_joint"/>
      <jointvel name="leg_r2_vel" joint="leg_r2_joint"/>
      <jointvel name="leg_r3_vel" joint="leg_r3_joint"/>
      <jointvel name="leg_r4_vel" joint="leg_r4_joint"/>
      <jointvel name="leg_r5_vel" joint="leg_r5_joint"/>
      <jointvel name="leg_r6_vel" joint="leg_r6_joint"/>

      <jointvel name="zarm_l1_vel" joint="zarm_l1_joint"/>
      <jointvel name="zarm_l2_vel" joint="zarm_l2_joint"/>
      <jointvel name="zarm_l3_vel" joint="zarm_l3_joint"/>
      <jointvel name="zarm_l4_vel" joint="zarm_l4_joint"/>
      <jointvel name="zarm_l5_vel" joint="zarm_l5_joint"/>
      <jointvel name="zarm_l6_vel" joint="zarm_l6_joint"/>
      <jointvel name="zarm_l7_vel" joint="zarm_l7_joint"/>

      <jointvel name="zarm_r1_vel" joint="zarm_r1_joint"/>
      <jointvel name="zarm_r2_vel" joint="zarm_r2_joint"/>
      <jointvel name="zarm_r3_vel" joint="zarm_r3_joint"/>
      <jointvel name="zarm_r4_vel" joint="zarm_r4_joint"/>
      <jointvel name="zarm_r5_vel" joint="zarm_r5_joint"/>
      <jointvel name="zarm_r6_vel" joint="zarm_r6_joint"/>
      <jointvel name="zarm_r7_vel" joint="zarm_r7_joint"/>
      <jointvel name="head_yaw_vel" joint="neck_motor"/>
      <jointvel name="head_pitch_vel" joint="head"/>
  </sensor>
</mujoco>
